### **Async/Await in JavaScript: Why and How**

**Async/await** is a modern syntax for handling asynchronous operations in JavaScript. It was introduced in ES2017 and builds on top of Promises, making asynchronous code easier to read and write.

---

### **Why Do We Need Async/Await?**

1. **Improves Readability**:

   - With promises, chaining `.then()` can sometimes get hard to follow, especially in complex workflows.
   - Async/await makes asynchronous code look more like synchronous code, improving clarity.

2. **Simplifies Error Handling**:

   - Instead of chaining `.catch()` at every step, async/await allows you to use `try-catch` blocks for a centralized approach.

3. **Easier Debugging**:

   - Async/await integrates better with debugging tools. Stack traces are more readable compared to promises.

4. **Sequential Execution**:
   - Async/await simplifies executing promises in sequence without nesting or chaining.

---

### **How Does It Work?**

- The `async` keyword before a function declares it as an **asynchronous function**.
- The `await` keyword pauses the execution of the function until the promise is resolved or rejected.
- Functions declared with `async` always return a promise.

---

### **Examples**

#### **1. Basic Async/Await**

```javascript
const fetchData = () => {
  return new Promise((resolve, reject) => {
    setTimeout(() => {
      resolve("Data fetched successfully!");
    }, 1000);
  });
};

// Using async/await
const getData = async () => {
  try {
    const data = await fetchData(); // Waits for the promise to resolve
    console.log(data);
  } catch (err) {
    console.error("Error:", err.message); // Handles any errors
  }
};

getData();
```

---

#### **2. Sequential Async Operations**

Compare this to chaining promises:

```javascript
const authenticate = () => Promise.resolve("User authenticated");
const fetchUserData = () => Promise.resolve("User data fetched");
const logActivity = () => Promise.resolve("Activity logged");

const userWorkflow = async () => {
  try {
    const auth = await authenticate();
    console.log(auth);

    const userData = await fetchUserData();
    console.log(userData);

    const log = await logActivity();
    console.log(log);
  } catch (err) {
    console.error("Error in workflow:", err.message);
  }
};

userWorkflow();
```

This is much cleaner and easier to read compared to promise chaining.

---

#### **3. Parallel Execution with `await`**

For independent tasks, you can use `Promise.all` with `await` to execute them in parallel.

```javascript
const fetchPosts = () =>
  new Promise((resolve) => setTimeout(() => resolve("Posts fetched"), 1000));
const fetchComments = () =>
  new Promise((resolve) => setTimeout(() => resolve("Comments fetched"), 1500));

const getDashboardData = async () => {
  try {
    const [posts, comments] = await Promise.all([
      fetchPosts(),
      fetchComments(),
    ]);
    console.log(posts, comments);
  } catch (err) {
    console.error("Error fetching dashboard data:", err.message);
  }
};

getDashboardData();
```

---

#### **4. Using `await` with Error Handling**

Instead of multiple `.catch()`, use `try-catch`.

```javascript
const riskyOperation = () => {
  return new Promise((_, reject) =>
    setTimeout(() => reject(new Error("Operation failed")), 1000)
  );
};

const performOperation = async () => {
  try {
    const result = await riskyOperation();
    console.log(result);
  } catch (err) {
    console.error("Caught Error:", err.message);
  }
};

performOperation();
```

---

#### **5. Retrying with Async/Await**

Retry logic becomes simpler with `async/await`.

```javascript
const fetchWithRetry = async (retries) => {
  try {
    const success = Math.random() > 0.7; // 30% success rate
    if (!success) throw new Error("Temporary failure");
    return "Data fetched successfully!";
  } catch (err) {
    if (retries > 0) {
      console.log(`Retrying... (${retries} retries left)`);
      return fetchWithRetry(retries - 1);
    } else {
      throw err;
    }
  }
};

const fetchData = async () => {
  try {
    const data = await fetchWithRetry(3);
    console.log(data);
  } catch (err) {
    console.error("Final Error:", err.message);
  }
};

fetchData();
```

---

### **Key Differences: Promises vs Async/Await**

| **Feature**    | **Promises**                              | **Async/Await**                             |
| -------------- | ----------------------------------------- | ------------------------------------------- |
| Syntax         | `.then()`, `.catch()`, `.finally()`       | `async`, `await`, `try-catch`               |
| Readability    | Can become hard to read in complex chains | Cleaner and looks like synchronous code     |
| Error Handling | `.catch()` per promise or chain           | Centralized with `try-catch`                |
| Debugging      | Complex stack traces                      | Easier debugging and stack trace visibility |

---

### **Best Practices for Async/Await**

1. **Always use `try-catch`**:
   - Prevent unhandled rejections by wrapping `await` calls in `try-catch`.
2. **Avoid Blocking**:
   - Use `Promise.all` for parallel tasks instead of waiting for each one sequentially unless required.
3. **Combine with Promises**:
   - Async/await is built on promises, so they can be combined when necessary.
4. **Don’t Forget to `await`**:
   - Missing `await` will result in unhandled promises.
5. **Keep Async Functions Modular**:
   - Write small, reusable async functions for better readability and maintainability.

---

### **When to Use Async/Await?**

- When you have multiple asynchronous operations that depend on each other.
- When readability and simplicity are a priority.
- When you need centralized error handling for a workflow.

---

## A list of questions on **async/await** to help strengthen your understanding:

---

### **Basics of Async/Await**

### 1. What does the `async` keyword do when added to a function?

The `async` keyword, when added to a function, transforms that function into an **asynchronous function**. This enables the function to return a **promise** and allows you to use the `await` keyword inside it to work with promises in a more synchronous-like manner.

### Key Effects of the `async` Keyword

1. **Return a Promise**:

   - Regardless of whether the function explicitly returns a value or not, an `async` function always returns a promise.
     - If the function returns a value, it automatically wraps that value in a resolved promise.
     - If the function throws an error, it automatically returns a rejected promise.

   **Example**:

   ```javascript
   async function example() {
     return "Hello, world!";
   }

   example().then((result) => console.log(result)); // Outputs: "Hello, world!"
   ```

2. **Enables the Use of `await`**:

   - The `async` keyword allows the use of the `await` keyword inside the function, which pauses the execution of the function until the promise is resolved (or rejected). This makes asynchronous code easier to write and read, as it allows you to work with promises as though they are synchronous.

   **Example**:

   ```javascript
   async function fetchData() {
     const response = await fetch("https://jsonplaceholder.typicode.com/posts");
     const data = await response.json();
     console.log(data);
   }

   fetchData(); // Asynchronous operation with await
   ```

3. **Implicit Promise Wrapping**:

   - Even if you don’t explicitly return a promise from an `async` function, it will always return a promise. This is helpful in situations where you need the function to be consistent with promise-based APIs.

   **Example**:

   ```javascript
   async function foo() {
     console.log("Doing something...");
     // Implicitly returns a resolved promise
   }

   foo().then(() => console.log("Function complete"));
   ```

### Behavior of `async` Functions

- **Resolved value**: If the function returns a value (e.g., `return 42;`), it returns `Promise.resolve(42)`.
- **Rejected value**: If the function throws an error (e.g., `throw new Error("Something went wrong");`), it returns `Promise.reject(error)`.

---

### **Detailed Example of an `async` Function**:

```javascript
async function example() {
  try {
    const data = await fetchDataFromAPI(); // This will pause until the Promise is resolved
    console.log("Data received:", data);
  } catch (error) {
    console.error("Error occurred:", error); // Catch any error thrown by async code
  }
}

function fetchDataFromAPI() {
  return new Promise((resolve, reject) => {
    setTimeout(() => {
      resolve("Fetched data successfully!");
    }, 1000);
  });
}

example(); // This will run asynchronously
```

**Explanation**:

1. `fetchDataFromAPI()` is an asynchronous function that returns a promise.
2. Inside the `async` function `example()`, the `await` keyword is used to wait for the `fetchDataFromAPI()` promise to resolve.
3. The `example()` function returns a promise, and you can use `.then()` or `await` to handle its completion.

---

### **Summary**:

- `async` makes a function return a promise.
- `await` can be used inside an `async` function to pause the function's execution until a promise resolves.
- `async/await` allows for more readable and manageable asynchronous code, especially when compared to traditional promise chains.

### 2. What does the `await` keyword do, and where can you use it?

### The `await` Keyword in JavaScript

The `await` keyword is used to **pause** the execution of an **asynchronous function** until a `Promise` is resolved or rejected. It can only be used inside **asynchronous functions** (i.e., functions marked with `async`).

### Key Points:

- **Pauses execution:** `await` pauses the execution of an `async` function until the promise is either resolved or rejected.
- **Returns the result:** Once the promise is resolved, `await` returns the result of the promise. If the promise is rejected, it throws an error.
- **Simplifies asynchronous code:** It allows you to write asynchronous code in a more **synchronous-looking manner**, making it easier to read and maintain.

### Syntax:

```javascript
const result = await somePromise;
```

- `await` can only be used within `async` functions. It cannot be used in regular (non-async) functions.

---

### Example of `await` with `async`:

```javascript
// Simulating an asynchronous operation (e.g., fetching data from an API)
function fetchData() {
  return new Promise((resolve, reject) => {
    setTimeout(() => {
      resolve("Data fetched successfully!");
    }, 2000);
  });
}

async function displayData() {
  console.log("Fetching data...");

  // Using await to pause the function execution until the Promise is resolved
  const data = await fetchData(); // waits for fetchData() to resolve
  console.log(data); // Logs the result after 2 seconds

  console.log("Data displayed!");
}

displayData();
```

### Explanation:

1. **`fetchData()`** simulates an asynchronous operation (like fetching data from an API). It returns a promise that resolves with the string `"Data fetched successfully!"` after 2 seconds.
2. **`displayData()`** is an asynchronous function that:
   - Logs `"Fetching data..."` immediately.
   - Pauses at `await fetchData()` until the promise returned by `fetchData()` resolves.
   - Once the promise resolves, it logs the fetched data and continues with the next steps.
3. The output will be:
   ```
   Fetching data...
   (after 2 seconds)
   Data fetched successfully!
   Data displayed!
   ```

---

### Where can you use `await`?

- **Inside `async` functions**: You can only use `await` inside a function declared with `async`.

  ```javascript
  async function example() {
    const result = await someAsyncFunction();
  }
  ```

- **With promises**: `await` can be used with any expression that returns a `Promise`. It waits for the promise to resolve and gives you the result or throws an error if rejected.

  ```javascript
  let data = await fetch("https://api.example.com/data");
  let jsonData = await data.json(); // if the first await is resolved, we can await again
  ```

---

### Example with Error Handling (try-catch):

Since `await` returns the result of the resolved promise, you might also want to handle errors when the promise is rejected:

```javascript
async function fetchDataWithErrorHandling() {
  try {
    const data = await fetchData();
    console.log("Data:", data);
  } catch (error) {
    console.error("Error:", error);
  }
}

fetchDataWithErrorHandling();
```

### Output:

```
Fetching data...
Data fetched successfully!
```

If `fetchData()` throws an error or is rejected, the `catch` block will handle it and log the error.

---

### Summary:

- **`await`** is used inside an `async` function to pause execution until a promise is resolved.
- It makes asynchronous code more readable by allowing you to write code that looks synchronous but is actually asynchronous.
- It can only be used within `async` functions.
- Errors in promises can be caught using `try-catch` blocks to handle rejections.

### 3. Write a simple `async` function that resolves a promise after 1 second and logs the result.

Here's a simple `async` function that resolves a promise after 1 second and logs the result:

```javascript
// Function that returns a Promise which resolves after 1 second
function resolveAfterOneSecond() {
  return new Promise((resolve) => {
    setTimeout(() => {
      resolve("Promise resolved after 1 second!");
    }, 1000);
  });
}

// Async function that waits for the Promise to resolve
async function fetchData() {
  const result = await resolveAfterOneSecond(); // Waits for the promise to resolve
  console.log(result); // Logs the result after 1 second
}

// Call the async function
fetchData();
```

### Explanation:

1. **`resolveAfterOneSecond()`**:

   - This function returns a promise that resolves with the message `"Promise resolved after 1 second!"` after 1 second (using `setTimeout`).

2. **`fetchData()`**:
   - This is an `async` function where the `await` keyword is used to pause execution until `resolveAfterOneSecond()` resolves its promise. Once resolved, it logs the result to the console.

### Output:

```
Promise resolved after 1 second!
```

This code demonstrates how `async`/`await` works in JavaScript to handle asynchronous operations. The message will be logged after 1 second, following the resolution of the promise.

### 4. How does an `async` function handle errors if there is no `try-catch` block?

If an `async` function encounters an error and there is no `try-catch` block to handle it, the error will be automatically **wrapped** in a rejected `Promise`. The `async` function will return a **rejected Promise** with the error as its reason.

This behavior is similar to how errors are handled with Promises: if a promise is rejected and there's no `.catch()` method or handler, the error will remain unhandled.

### Example: Error Handling Without `try-catch` in `async` Function

```javascript
// Function that returns a Promise that rejects after 1 second
function rejectAfterOneSecond() {
  return new Promise((_, reject) => {
    setTimeout(() => {
      reject("Something went wrong!");
    }, 1000);
  });
}

// Async function without try-catch block
async function fetchData() {
  const result = await rejectAfterOneSecond(); // Will throw an error (Promise rejection)
  console.log(result);
}

fetchData();
```

### Explanation:

1. **`rejectAfterOneSecond()`** returns a promise that rejects after 1 second with the message `"Something went wrong!"`.
2. **`fetchData()`** is an `async` function that uses `await` to wait for the promise from `rejectAfterOneSecond()`. Since the promise is rejected, an error occurs, but there is no `try-catch` block to handle the rejection.
3. The **error** will not be caught, and the `fetchData()` function will return a **rejected promise**.

### Output:

```
Uncaught (in promise) Something went wrong!
```

---

### Uncaught Promise Rejections:

- If an `async` function encounters an error and there's no `try-catch`, the error will propagate and cause the promise returned by the `async` function to be rejected.
- In a **browser environment**, the error will appear in the console as an "uncaught (in promise)" warning.
- In **Node.js** (from version 15 onwards), unhandled promise rejections will terminate the process by default, unless configured otherwise.

---

### Proper Error Handling with `try-catch`:

To handle errors within an `async` function, you should use a `try-catch` block:

```javascript
async function fetchData() {
  try {
    const result = await rejectAfterOneSecond(); // Will throw an error
    console.log(result);
  } catch (error) {
    console.log("Error:", error); // Catches the error
  }
}

fetchData();
```

### Output:

```
Error: Something went wrong!
```

### 5. Can you use `await` outside of an `async` function? Why or why not?

No, you **cannot** use the `await` keyword outside of an `async` function in JavaScript. This is because `await` is designed specifically to be used inside `async` functions, and it works by pausing the execution of the surrounding `async` function until the promise is resolved or rejected.

### Why can't `await` be used outside of an `async` function?

- **`await` is only valid inside `async` functions**: The JavaScript engine requires `await` to be inside a function that is declared with `async`. When you use `await`, JavaScript pauses the function execution until the promise resolves, which is a behavior that is only available within `async` functions.
- **Global or non-`async` function context**: Outside of `async` functions, there’s no function context that the JavaScript engine can pause. Thus, attempting to use `await` outside an `async` function would lead to a syntax error.

### Example: Using `await` Outside an `async` Function (Invalid)

```javascript
// This will throw a syntax error because `await` is used outside an `async` function
const result = await Promise.resolve("Hello"); // SyntaxError: Unexpected token 'await'
```

### Correct Way to Use `await`:

To use `await`, you must wrap it inside an `async` function:

```javascript
async function fetchData() {
  const result = await Promise.resolve("Hello");
  console.log(result); // Logs: "Hello"
}

fetchData();
```

### Using `await` at the Top Level (in Modern JavaScript Environments)

Starting from **ECMAScript 2022 (ES2022)**, it is now allowed to use `await` at the **top level** in **modules**. In this case, you can use `await` outside of an `async` function, but only if your script is a **module** (i.e., using `<script type="module">` in the browser or `.mjs` files in Node.js).

```javascript
// In a module (e.g., script type="module" in HTML)
const result = await Promise.resolve("Hello");
console.log(result); // Logs: "Hello"
```

In this case, `await` works at the top level because the JavaScript engine treats the module as an implicit `async` function. However, this is specific to modules and not applicable to regular script files.

### Summary:

- **In non-`async` functions or global scope**, `await` will cause a syntax error.
- **Inside an `async` function**, `await` works to pause the function execution until a promise is resolved.
- **Top-level `await`** is allowed in **modules** but not in standard scripts.

---

### **Error Handling**

### 6. How do you handle errors in an `async` function? Write an example using `try-catch`.

To handle errors in an `async` function, you can use a `try-catch` block. The `try` block is used to execute code that might throw an error, and the `catch` block is used to handle any errors that occur during the execution of the code inside the `try` block.

### Basic Syntax:

```javascript
async function myAsyncFunction() {
  try {
    // Code that might throw an error (like awaiting a rejected promise)
    const result = await someAsyncOperation();
    console.log(result);
  } catch (error) {
    // Handle any errors that occur
    console.error("Error caught:", error);
  }
}
```

In this setup:

- The `await` expression inside the `try` block pauses the execution of the function until the `Promise` resolves or rejects.
- If the `Promise` is rejected, the error is caught in the `catch` block, allowing you to handle the error appropriately.

### Example: Handling Errors in an `async` function

Let's consider an example where we simulate an asynchronous operation that may either resolve successfully or reject with an error.

```javascript
// Simulating an asynchronous operation that may fail
function fetchData(success) {
  return new Promise((resolve, reject) => {
    setTimeout(() => {
      if (success) {
        resolve("Data fetched successfully!");
      } else {
        reject("Failed to fetch data.");
      }
    }, 1000);
  });
}

async function displayData(success) {
  try {
    const result = await fetchData(success); // Attempt to fetch data
    console.log(result); // Log the successful result
  } catch (error) {
    console.error("Error:", error); // Handle the error if the promise is rejected
  }
}

// Call the function with a successful result
displayData(true); // Logs: Data fetched successfully!

// Call the function with a failure
displayData(false); // Logs: Error: Failed to fetch data.
```

### Explanation:

1. **`fetchData(success)`**:

   - This function returns a `Promise` that resolves with a success message if `success` is `true`, or rejects with an error message if `success` is `false`.

2. **`displayData(success)`**:

   - This is an `async` function. The `await` keyword pauses the execution of the function until the `fetchData(success)` promise either resolves or rejects.
   - If the promise resolves, the result is logged to the console.
   - If the promise is rejected (an error occurs), the `catch` block catches the error and logs it.

3. **Error Handling**:
   - If `displayData(false)` is called, the promise is rejected, and the `catch` block handles the error by logging `"Error: Failed to fetch data."`.
   - If `displayData(true)` is called, the promise resolves, and the success message is logged.

### Output:

```
Data fetched successfully!
Error: Failed to fetch data.
```

### Key Points:

- The `try-catch` block ensures that errors (rejected promises) are caught and handled gracefully.
- You can use the `catch` block to log errors, display messages, or take corrective actions when a promise is rejected.

### 7. What happens if an error is thrown inside an `async` function?

When an error is thrown inside an `async` function, it is treated as a **rejected promise**. This means that the error is captured as the reason for the promise rejection. If the error is not handled inside the `async` function using a `try-catch` block, the promise returned by the `async` function will be rejected, and the error will propagate outside of it.

### Key Points:

- **Error inside an `async` function**: When an error is thrown inside an `async` function (whether explicitly using `throw` or implicitly by rejecting a promise), it will cause the promise returned by that function to be rejected.
- **Uncaught errors**: If the `async` function is called without proper error handling (like `try-catch`), the promise will be rejected, and the error will be uncaught unless it is handled using `.catch()` or inside an outer `try-catch` block.

### Example 1: Throwing an Error Inside an `async` Function

```javascript
async function fetchData() {
  // Throwing an error inside the async function
  throw new Error("Something went wrong!");
}

fetchData()
  .then((result) => console.log(result)) // This won't be reached
  .catch((error) => console.log("Caught error:", error)); // Logs: Caught error: Error: Something went wrong!
```

### Explanation:

- The `fetchData()` function throws an error, which causes the returned promise to be rejected.
- The `catch` block (attached to the `fetchData()` promise) catches the rejection and logs the error.

### Example 2: Handling Error Inside the `async` Function

You can also handle the error inside the `async` function itself using `try-catch`:

```javascript
async function fetchData() {
  try {
    // Throwing an error inside the async function
    throw new Error("Something went wrong!");
  } catch (error) {
    console.log("Error caught inside async function:", error.message); // Logs: Error caught inside async function: Something went wrong!
  }
}

fetchData();
```

### Explanation:

- Inside the `fetchData()` function, we use a `try-catch` block to handle the error. The error is caught, and its message is logged inside the `catch` block.

### Example 3: Error Propagation (Uncaught Error)

If an error occurs inside an `async` function and is not caught, the promise returned by the function will be rejected, and you will need to handle it externally:

```javascript
async function fetchData() {
  // Throwing an error
  throw new Error("Data not found!");
}

fetchData(); // Promise will be rejected, and we won't handle it here.
```

In this case, the promise returned by `fetchData()` will be rejected, and the error will not be handled, leading to an **unhandled promise rejection**. In modern JavaScript (Node.js v15+ and browsers), unhandled promise rejections may result in warnings or errors in the console.

To handle this, you can use `.catch()` or `try-catch` as shown in the previous examples.

### Summary:

- **If an error is thrown inside an `async` function**, it will cause the function's promise to be rejected.
- **If there is no `try-catch` block inside the `async` function**, the rejection can be handled outside using `.catch()` or other promise handlers.
- **If there is a `try-catch` block**, the error can be caught and handled inside the `async` function itself.
- **Unhandled promise rejections** can cause warnings or errors, especially in newer versions of Node.js or browsers.

### 8. Write an `async` function that fetches user data but falls back to default data if an error occurs.

Here’s an example of an `async` function that attempts to fetch user data from a remote source. If the fetch operation fails (for example, due to network issues or invalid data), it will fall back to using default data.

### Example Code:

```javascript
async function fetchUserData() {
  // Default user data to fall back on if fetching fails
  const defaultData = {
    name: "John Doe",
    age: 30,
    email: "johndoe@example.com",
  };

  try {
    // Simulating a fetch request (you can replace it with a real API call)
    const response = await fetch("https://api.example.com/user"); // Simulated API endpoint
    if (!response.ok) {
      throw new Error("Failed to fetch user data");
    }
    const data = await response.json();
    return data; // Return the fetched data if successful
  } catch (error) {
    console.error("Error fetching user data:", error);
    return defaultData; // Return default data if an error occurs
  }
}

// Call the async function
fetchUserData()
  .then((data) => console.log("User Data:", data))
  .catch((error) => console.error("Error:", error));
```

### Explanation:

1. **`defaultData`**: This is the fallback data that will be used if the fetch operation fails.
2. **`fetchUserData()`**:
   - The function attempts to fetch data from a simulated API endpoint (`https://api.example.com/user`).
   - If the `fetch()` request fails (either because of a network error or the response is not `ok`), the function catches the error using a `try-catch` block.
   - If an error occurs, the function logs the error and returns the `defaultData` instead.
3. **`.then()` and `.catch()`**:
   - We use `.then()` to handle the successful resolution of the `fetchUserData()` promise and log the user data.
   - If the promise is rejected (i.e., an error occurs), `.catch()` is used to handle any unexpected errors.

### Example Output (if fetch fails):

```
Error fetching user data: Error: Failed to fetch user data
User Data: { name: 'John Doe', age: 30, email: 'johndoe@example.com' }
```

### Example Output (if fetch is successful):

```
User Data: { name: 'Jane Smith', age: 25, email: 'janesmith@example.com' }
```

### Notes:

- The `catch` block ensures that if the `fetch()` operation fails, the function will not crash, and it will fall back to the default data.
- This pattern is useful for handling network errors or cases where data might be missing from the API.

### 9. Can you mix `try-catch` and `.catch()` for error handling? Explain with an example.

Yes, you can **mix** `try-catch` and `.catch()` for error handling in JavaScript, especially when you're working with `async` functions. While `try-catch` is used for synchronous error handling within the `async` function, `.catch()` is used for handling errors in the returned promise (if an error wasn't handled inside the function).

### How It Works:

- **`try-catch`** is used within an `async` function to handle errors that occur during `await` calls or any synchronous code.
- **`.catch()`** can be used to handle errors that might propagate from the `async` function, particularly when calling the `async` function itself.

### Example: Mixing `try-catch` and `.catch()`

```javascript
async function fetchData() {
  const defaultData = {
    name: "John Doe",
    age: 30,
    email: "johndoe@example.com",
  };

  try {
    // Simulating a fetch request (you can replace it with a real API call)
    const response = await fetch("https://api.example.com/user"); // Simulated API endpoint
    if (!response.ok) {
      throw new Error("Failed to fetch user data");
    }
    const data = await response.json();
    return data; // Return the fetched data if successful
  } catch (error) {
    console.error("Error inside async function:", error);
    return defaultData; // Return default data if an error occurs
  }
}

// Call the async function and handle errors using .catch() outside
fetchData()
  .then((data) => {
    console.log("User Data:", data);
  })
  .catch((error) => {
    console.log("Error caught outside:", error); // This will catch any unhandled error outside
  });
```

### Explanation:

1. **`fetchData()`**:
   - This function attempts to fetch data from an API using `fetch()`. If it fails, it will throw an error, which is caught by the `try-catch` block inside the function.
   - If the data cannot be fetched, the error is logged inside the `catch` block, and the function returns `defaultData`.
2. **`.then()`**:

   - After calling `fetchData()`, the `.then()` block handles the returned value (data) if the promise resolves successfully.

3. **`.catch()`**:
   - In case any unhandled errors occur (for example, if `fetchData()` fails and the error isn't properly handled inside the function), `.catch()` will handle the rejection and log the error.

### What happens here:

- **If everything goes smoothly** (i.e., the `fetch()` succeeds), the data is returned from `fetchData()`, and the `then()` block logs the result.
- **If an error occurs** inside the `fetchData()` function (e.g., the fetch fails), the `catch` inside `fetchData()` will catch the error and provide the fallback `defaultData`.
- **If there's an unhandled error outside** (say, from other asynchronous operations), it will be caught by the `.catch()` attached to the promise returned by `fetchData()`.

### Example Output:

1. **If fetch is successful**:

```
User Data: { name: 'Jane Smith', age: 25, email: 'janesmith@example.com' }
```

2. **If fetch fails (or throws an error inside)**:

```
Error inside async function: Error: Failed to fetch user data
User Data: { name: 'John Doe', age: 30, email: 'johndoe@example.com' }
```

### Key Takeaways:

- **Inside `async` functions**: `try-catch` handles synchronous errors and errors from `await`.
- **Outside `async` functions**: `.catch()` can be used to catch unhandled promise rejections.
- **Mixing them**: You can use `try-catch` inside the function to handle specific errors and `.catch()` outside to handle any unhandled promise rejections or errors in the returned promise.

### 10. What are unhandled promise rejections, and how can you prevent them when using `async/await`?

### What are Unhandled Promise Rejections?

An **unhandled promise rejection** occurs when a `Promise` is rejected, but no code is in place to handle the rejection (using `.catch()`, `try-catch`, or similar mechanisms). This is particularly relevant when using `async/await`, as `async` functions return promises that may be rejected, and if no error handling is in place, it can result in an unhandled promise rejection.

### Why are Unhandled Promise Rejections Important?

In JavaScript, unhandled promise rejections can lead to unexpected behavior, which can be especially problematic in production environments. Earlier versions of Node.js and browsers used to silently ignore unhandled rejections. However, as of recent updates:

- **Node.js**: Starting from version 15, unhandled promise rejections will cause the process to exit with a non-zero exit code.
- **Browsers**: They log warnings in the console for unhandled promise rejections, but the script continues to run.

### Example of an Unhandled Promise Rejection:

Consider the following example:

```javascript
async function fetchData() {
  throw new Error("Failed to fetch data");
}

fetchData(); // No error handling here, so it's an unhandled promise rejection
```

### What happens:

- The `fetchData()` function throws an error, which causes the promise to be rejected.
- However, there is no `.catch()` or `try-catch` block around it, so this will result in an unhandled promise rejection.

### How to Prevent Unhandled Promise Rejections in `async/await`

#### 1. Using `try-catch` Inside `async` Functions

A `try-catch` block inside the `async` function can handle errors during the execution of asynchronous operations (like `await`).

```javascript
async function fetchData() {
  try {
    throw new Error("Failed to fetch data");
  } catch (error) {
    console.error("Caught error:", error.message); // Logs: Caught error: Failed to fetch data
  }
}

fetchData();
```

- **Explanation**: The `throw` inside the `async` function is caught by the `catch` block, preventing the unhandled promise rejection.

#### 2. Handling Rejections Outside `async` Functions Using `.catch()`

You can also handle the rejection of a promise returned by an `async` function using `.catch()`.

```javascript
async function fetchData() {
  throw new Error("Failed to fetch data");
}

fetchData().catch((error) => {
  console.error("Handled error outside:", error.message); // Logs: Handled error outside: Failed to fetch data
});
```

- **Explanation**: The `.catch()` method attached to the returned promise handles the rejection, so no unhandled promise rejection occurs.

#### 3. Global Unhandled Promise Rejection Handler (for Node.js)

In Node.js, you can handle unhandled promise rejections globally using the `unhandledRejection` event.

```javascript
process.on("unhandledRejection", (reason, promise) => {
  console.error("Unhandled promise rejection:", reason);
  // Optionally, you can decide to terminate the process
  process.exit(1); // Exit the process with a non-zero code
});

// Example of an unhandled rejection
async function fetchData() {
  throw new Error("Failed to fetch data");
}

fetchData(); // This will be caught by the global handler
```

- **Explanation**: The `unhandledRejection` event listens for any unhandled promise rejections and logs them. You can also choose to exit the process if necessary.

### Summary of Ways to Prevent Unhandled Promise Rejections:

1. **Use `try-catch` inside `async` functions** to catch and handle errors within the function.
2. **Use `.catch()` on the promise** returned by an `async` function to handle errors outside the function.
3. **Use a global handler** in Node.js (`process.on('unhandledRejection')`) to catch unhandled promise rejections globally.
4. **Always handle promises properly**—either by using `try-catch`, `.catch()`, or a combination of both—so that errors are caught and dealt with appropriately.

---

### **Sequential Execution**

### 11. Write an `async` function that performs the following tasks sequentially:

    - Log "Start".
    - Wait for 2 seconds.
    - Log "End".

Here’s an `async` function that performs the tasks you’ve mentioned sequentially:

```javascript
async function performTasks() {
  console.log("Start");

  // Wait for 2 seconds (using setTimeout wrapped in a Promise)
  await new Promise((resolve) => setTimeout(resolve, 2000));

  console.log("End");
}

// Call the async function
performTasks();
```

### Explanation:

1. **`console.log("Start")`**: This logs the message `"Start"` immediately when the function is called.
2. **`await new Promise(resolve => setTimeout(resolve, 2000))`**: This causes the function to wait for 2 seconds. The `setTimeout` function is wrapped in a `Promise` to allow the `await` to pause the execution.
3. **`console.log("End")`**: After the 2-second delay, `"End"` is logged to the console.

### Output:

```
Start
(Waits for 2 seconds)
End
```

### 12. Why is `await` useful for sequential execution compared to chaining promises?

The `await` keyword is useful for sequential execution in JavaScript because it allows for a more **synchronous-like** flow of code, making it easier to read and write compared to chaining multiple promises using `.then()`. Here's a breakdown of why `await` is preferred for sequential execution compared to chaining promises:

### 1. **More Readable Code (Synchronous Style)**

With `await`, the code appears more like traditional, synchronous code, making it easier to follow the flow of execution. Each `await` pauses the function until the promise is resolved, creating a natural, step-by-step sequence.

#### Example with `await`:

```javascript
async function sequentialTasks() {
  console.log("Start");
  await new Promise((resolve) => setTimeout(resolve, 2000)); // Wait for 2 seconds
  console.log("Middle");
  await new Promise((resolve) => setTimeout(resolve, 1000)); // Wait for 1 second
  console.log("End");
}

sequentialTasks();
```

**Explanation**:

- The `await` keyword pauses execution at each point and ensures that the next step only happens after the promise is resolved. The flow is easy to follow because it looks like synchronous code.

### 2. **Easier to Handle Errors**

With `await`, you can use `try-catch` blocks to handle errors in a clean and straightforward way. This makes error handling more intuitive compared to using `.catch()` with chained promises.

#### Example with `await` and `try-catch`:

```javascript
async function sequentialTasks() {
  try {
    console.log("Start");
    await new Promise((resolve) => setTimeout(resolve, 2000)); // Wait for 2 seconds
    console.log("Middle");
    await new Promise((resolve) => setTimeout(resolve, 1000)); // Wait for 1 second
    console.log("End");
  } catch (error) {
    console.error("Error occurred:", error);
  }
}

sequentialTasks();
```

**Explanation**:

- If an error occurs in any `await` statement, it can be caught by the `try-catch` block, which is much cleaner than chaining `.catch()` for each promise in promise chaining.

### 3. **No Nested Callbacks (Avoids "Callback Hell")**

When you use promise chaining (i.e., `.then()`), it often leads to nested callbacks, especially if you have multiple asynchronous operations in sequence. This can lead to less readable code, sometimes referred to as "callback hell" or "pyramid of doom."

#### Example with Promise Chaining:

```javascript
function sequentialTasks() {
  console.log("Start");
  new Promise((resolve) => setTimeout(resolve, 2000)) // Wait for 2 seconds
    .then(() => {
      console.log("Middle");
      return new Promise((resolve) => setTimeout(resolve, 1000)); // Wait for 1 second
    })
    .then(() => {
      console.log("End");
    })
    .catch((error) => {
      console.error("Error occurred:", error);
    });
}

sequentialTasks();
```

**Explanation**:

- While this code works, it is harder to read and manage as the number of chained promises increases. Each `.then()` adds a new level of nesting, and handling errors can get more complex.

### 4. **No Need for Manual Chaining of `.then()`**

With `await`, you don’t need to manually chain `.then()` statements, making the code more concise and readable. It allows you to handle asynchronous code in a linear fashion, which makes it easier to maintain, especially when dealing with a large number of promises.

### 5. **Parallel Execution with `await`** (Still Possible)

You can also execute promises in parallel using `Promise.all()` when needed, which is more efficient. The flexibility of `await` doesn’t mean you have to execute everything sequentially. For example, when some operations don’t depend on each other, you can execute them in parallel.

#### Example of Parallel Execution with `await`:

```javascript
async function parallelTasks() {
  console.log("Start");

  const task1 = new Promise((resolve) => setTimeout(resolve, 2000)); // Wait for 2 seconds
  const task2 = new Promise((resolve) => setTimeout(resolve, 1000)); // Wait for 1 second

  await Promise.all([task1, task2]); // Wait for both tasks to complete in parallel

  console.log("End");
}

parallelTasks();
```

**Explanation**:

- Even with `await`, you can wait for multiple promises to resolve in parallel using `Promise.all()`. This lets you leverage `await` for both sequential and parallel executions.

---

### Comparison of `await` vs. `.then()` Chaining

#### With `await`:

```javascript
async function fetchData() {
  console.log("Start fetching...");
  const data1 = await fetch("https://api.example.com/data1");
  const result1 = await data1.json();
  const data2 = await fetch("https://api.example.com/data2");
  const result2 = await data2.json();
  console.log(result1, result2);
}

fetchData();
```

#### With `.then()`:

```javascript
function fetchData() {
  console.log("Start fetching...");
  fetch("https://api.example.com/data1")
    .then((response1) => response1.json())
    .then((result1) => {
      fetch("https://api.example.com/data2")
        .then((response2) => response2.json())
        .then((result2) => {
          console.log(result1, result2);
        })
        .catch((error) => console.error("Error fetching data2:", error));
    })
    .catch((error) => console.error("Error fetching data1:", error));
}

fetchData();
```

### Key Differences:

- **Readability**: `await` is more readable and looks like synchronous code, whereas `.then()` involves chaining and nesting.
- **Error Handling**: `await` can use `try-catch` for all errors in a natural way, while `.then()` requires `.catch()` for each promise.
- **Sequence Control**: `await` allows sequential execution of promises naturally, while `.then()` requires more complex chaining.
- **Parallel Execution**: You can still handle parallel execution with `await` using `Promise.all()`, whereas `.then()` requires manually managing parallel promises.

### Conclusion:

`await` simplifies asynchronous programming by allowing you to write asynchronous code in a more synchronous manner, improving readability, error handling, and maintainability compared to chaining `.then()` methods. It's a powerful tool for handling sequential tasks while keeping the code clean and easy to follow.

### 13. Refactor a promise chain into an `async` function with sequential `await` calls.

Let's take a promise chain and refactor it into an `async` function using sequential `await` calls. Here's an example:

### Original Promise Chain:

```javascript
fetch("https://api.example.com/data1")
  .then((response1) => response1.json())
  .then((result1) => {
    console.log("Data 1:", result1);
    return fetch("https://api.example.com/data2");
  })
  .then((response2) => response2.json())
  .then((result2) => {
    console.log("Data 2:", result2);
    return fetch("https://api.example.com/data3");
  })
  .then((response3) => response3.json())
  .then((result3) => {
    console.log("Data 3:", result3);
  })
  .catch((error) => console.error("Error:", error));
```

### Refactored `async` Function with `await`:

```javascript
async function fetchData() {
  try {
    const response1 = await fetch("https://api.example.com/data1");
    const result1 = await response1.json();
    console.log("Data 1:", result1);

    const response2 = await fetch("https://api.example.com/data2");
    const result2 = await response2.json();
    console.log("Data 2:", result2);

    const response3 = await fetch("https://api.example.com/data3");
    const result3 = await response3.json();
    console.log("Data 3:", result3);
  } catch (error) {
    console.error("Error:", error);
  }
}

fetchData();
```

### Key Differences:

1. **Sequential Execution**: Using `await` in an `async` function makes each API call sequential. The function waits for the promise to resolve before moving to the next step, unlike in promise chaining where each `.then()` triggers the next step.
2. **Error Handling**: In the refactored version, all errors can be caught using a single `try-catch` block, while in the promise chain, each `.catch()` is used individually.

3. **Code Readability**: The `async`/`await` version is more readable and behaves in a way that is closer to synchronous code, whereas the promise chain has more nesting, which can be harder to follow as the number of steps increases.

Both approaches achieve the same result, but the `async`/`await` version provides a cleaner, more manageable way to handle sequential asynchronous calls.

### 14. What happens if you don’t use `await` before a promise inside an `async` function?

If you don't use `await` before a promise inside an `async` function, the function will not wait for the promise to resolve before continuing to the next line of code. Instead, the function will immediately proceed to the next statement, returning a **promise** that resolves asynchronously.

### Key Points:

1. **Without `await`**: The promise is not awaited, and the `async` function returns a promise that resolves with the value of the next expression. The function will not pause execution to wait for the promise to resolve.

2. **Async Function Returns a Promise**: An `async` function always returns a promise. If you don't use `await`, it won't wait for the promise to resolve and will return a pending promise instead.

### Example:

```javascript
async function fetchData() {
  const promise1 = fetch("https://api.example.com/data1"); // No await
  const result1 = await promise1.json(); // This waits, but promise1 is not awaited.
  console.log(result1);
}

fetchData();
```

### Explanation:

- **Without `await`**:
  - `promise1` is assigned the `fetch()` call, which returns a promise.
  - The `await` keyword is used on `result1`, meaning the code will still wait for the `promise1` to resolve before it proceeds to the next line.
  - However, the function itself does not wait for `promise1` before it moves on, so the `fetch()` call is effectively non-blocking.

### What Happens Internally:

- The `fetch()` function initiates the HTTP request, but since there’s no `await`, the function doesn’t wait for the result.
- If you don't `await` the promise but attempt to access its result (like calling `.json()`), it will throw an error or cause unintended behavior because the promise hasn’t been resolved yet.

### Corrected Version with `await`:

```javascript
async function fetchData() {
  const response1 = await fetch("https://api.example.com/data1"); // Now await the promise
  const result1 = await response1.json(); // Wait for response1 to resolve
  console.log(result1);
}

fetchData();
```

In this case, the function will correctly wait for `fetch()` to resolve before trying to call `.json()` on the response.

### Summary:

- If you don't use `await` before a promise inside an `async` function, the function will return a pending promise immediately, and execution will not pause.
- This may lead to unexpected behavior or errors when trying to access the result of the promise.
- To ensure proper sequential execution, always use `await` before promises inside `async` functions.

### 15. Write an `async` function that fetches user info and their posts one after the other and logs the results.

Here’s an example of an `async` function that fetches user information and their posts one after the other and logs the results. We'll assume that the API endpoints are something like `https://api.example.com/users/{userId}` for the user info and `https://api.example.com/posts?userId={userId}` for the posts.

### Example:

```javascript
async function fetchUserData(userId) {
  try {
    // Fetch user info
    const userResponse = await fetch(`https://api.example.com/users/${userId}`);
    const userInfo = await userResponse.json();
    console.log("User Info:", userInfo);

    // Fetch posts of the user
    const postsResponse = await fetch(
      `https://api.example.com/posts?userId=${userId}`
    );
    const posts = await postsResponse.json();
    console.log("User Posts:", posts);
  } catch (error) {
    console.error("Error fetching data:", error);
  }
}

// Example: Fetching user data for user with ID 1
fetchUserData(1);
```

### Explanation:

1. **Fetching User Info**:

   - `await fetch(...)`: The `await` ensures that the fetch call for user information is completed before proceeding to the next step.
   - `await userResponse.json()`: After the user data is fetched, `.json()` is called to parse the JSON response.

2. **Fetching Posts**:

   - After the user info is fetched and logged, the function proceeds to fetch the posts for the user using the `userId`.
   - `await fetch(...)` and `await postsResponse.json()` handle the fetching and parsing of the posts.

3. **Error Handling**:
   - The `try-catch` block ensures that if any error occurs during the fetching process, it is caught and logged to the console.

### Output (Example):

```
User Info: { id: 1, name: "John Doe", email: "john.doe@example.com" }
User Posts: [
    { id: 1, title: "Post 1", body: "Content of post 1" },
    { id: 2, title: "Post 2", body: "Content of post 2" }
]
```

---

### **Parallel Execution**

### 16. Explain the difference between using `await` in a loop and using `Promise.all` for parallel execution.

When working with asynchronous operations inside loops, there are two main approaches to consider for handling promises:

1. **Using `await` in a loop (sequential execution)**
2. **Using `Promise.all` (parallel execution)**

Let’s break down the differences between these two approaches:

### 1. **Using `await` in a loop (Sequential Execution)**

When you use `await` inside a loop (e.g., a `for`, `for...of`, or `while` loop), each asynchronous operation is executed **one after another**, meaning the next iteration will not start until the current iteration's promise is resolved.

#### Example:

```javascript
async function fetchDataSequentially(urls) {
  for (let url of urls) {
    const response = await fetch(url); // Wait for the response for each URL
    const data = await response.json(); // Wait for the data to be parsed
    console.log(data);
  }
}

const urls = [
  "https://api.example.com/data1",
  "https://api.example.com/data2",
  "https://api.example.com/data3",
];
fetchDataSequentially(urls);
```

#### Explanation:

- The first `fetch` call will start and the function will **wait** for the promise to resolve before continuing to the next iteration.
- This means that each request will be completed **sequentially**—one after the other.
- The next API call will only be made after the current call has completed.

#### Pros:

- **Simple to implement**: This approach works well when each operation depends on the previous one or when order matters.
- **Clear and readable**: The flow of the code looks synchronous, which can be easier to understand.

#### Cons:

- **Slower execution**: If there are many asynchronous operations, this can lead to long waiting times since they are executed one by one.

### 2. **Using `Promise.all` (Parallel Execution)**

In contrast, when you use `Promise.all`, all the asynchronous operations are initiated **at the same time** (in parallel), and you wait for **all promises to resolve** before proceeding.

#### Example:

```javascript
async function fetchDataInParallel(urls) {
  const promises = urls.map((url) =>
    fetch(url).then((response) => response.json())
  ); // Create an array of promises
  const results = await Promise.all(promises); // Wait for all promises to resolve
  console.log(results);
}

const urls = [
  "https://api.example.com/data1",
  "https://api.example.com/data2",
  "https://api.example.com/data3",
];
fetchDataInParallel(urls);
```

#### Explanation:

- `urls.map(url => fetch(url).then(response => response.json()))`: This creates an array of promises by initiating each `fetch` request immediately, without waiting for the previous one to finish.
- `await Promise.all(promises)`: This waits for **all promises** in the array to resolve and returns an array of their results.
- All the `fetch` requests are executed **in parallel**.

#### Pros:

- **Faster execution**: If there’s no dependency between the operations, `Promise.all` will run all promises in parallel, potentially completing much faster than executing them sequentially.
- **Optimized for independent operations**: If the operations don’t rely on each other’s results, `Promise.all` is the more efficient choice.

#### Cons:

- **More complex error handling**: With `Promise.all`, if any single promise in the array rejects, the entire `Promise.all` will reject, and handling multiple errors might be more complicated.
- **Resource limits**: If you initiate too many requests in parallel, you might run into resource limits (e.g., network congestion, API rate limits, etc.).

### Key Differences:

| **Aspect**           | **Using `await` in a loop**                           | **Using `Promise.all`**                                     |
| -------------------- | ----------------------------------------------------- | ----------------------------------------------------------- |
| **Execution Order**  | Sequential (one after the other)                      | Parallel (all at once)                                      |
| **Speed**            | Slower (since operations are one by one)              | Faster (as all operations run at the same time)             |
| **Error Handling**   | Errors are handled per iteration (easier)             | If one promise fails, all fail (more complex)               |
| **Use Case**         | When operations depend on each other or order matters | When operations are independent and can be done in parallel |
| **Code Readability** | Simple and easy to understand                         | Can be more difficult to manage errors                      |

### When to Use Each Approach:

- **Use `await` in a loop**:

  - When the asynchronous tasks **depend on each other** (e.g., the result of one API call is needed before the next can proceed).
  - When the order of execution is important, and you need to control the flow of operations one step at a time.

- **Use `Promise.all`**:
  - When the asynchronous tasks are **independent** (e.g., multiple API calls that don't rely on each other’s results).
  - When you want to **speed up** the process by executing the tasks concurrently.
  - When you need all tasks to finish before proceeding with further logic.

### Example: Speed Comparison

Here’s an example where we fetch data from three different URLs:

#### Using `await` in a loop:

```javascript
async function fetchDataSequentially(urls) {
  const start = Date.now();
  for (let url of urls) {
    const response = await fetch(url);
    const data = await response.json();
  }
  const end = Date.now();
  console.log(`Sequential execution took ${end - start} ms`);
}

const urls = ["url1", "url2", "url3"];
fetchDataSequentially(urls);
```

#### Using `Promise.all`:

```javascript
async function fetchDataInParallel(urls) {
  const start = Date.now();
  const promises = urls.map((url) =>
    fetch(url).then((response) => response.json())
  );
  await Promise.all(promises);
  const end = Date.now();
  console.log(`Parallel execution took ${end - start} ms`);
}

const urls = ["url1", "url2", "url3"];
fetchDataInParallel(urls);
```

In most cases, **parallel execution with `Promise.all`** will be significantly faster than sequential execution with `await` in a loop, especially if the tasks are independent and can run concurrently.

### Conclusion:

- Use `await` in a loop when you need sequential execution (e.g., when one operation depends on the result of the previous one).
- Use `Promise.all` when you want to execute multiple promises in parallel for faster completion when the tasks are independent.

### 17. Write an `async` function that fetches data from three APIs in parallel and logs the results.

Here's an example of an `async` function that fetches data from three APIs in parallel and logs the results using `Promise.all`:

### Example:

```javascript
async function fetchDataInParallel() {
  try {
    // Array of API URLs
    const urls = [
      "https://api.example.com/data1",
      "https://api.example.com/data2",
      "https://api.example.com/data3",
    ];

    // Create an array of promises by fetching data from all APIs
    const promises = urls.map((url) =>
      fetch(url).then((response) => response.json())
    );

    // Wait for all promises to resolve
    const [data1, data2, data3] = await Promise.all(promises);

    // Log the results from all APIs
    console.log("Data 1:", data1);
    console.log("Data 2:", data2);
    console.log("Data 3:", data3);
  } catch (error) {
    console.error("Error fetching data:", error);
  }
}

// Call the function to fetch data
fetchDataInParallel();
```

### Explanation:

1. **Array of URLs**: The `urls` array contains the API endpoints you want to fetch data from.
2. **Mapping URLs to Promises**: The `map()` function is used to create an array of promises. Each `fetch()` request is made, and its result is converted to JSON using `.json()`.
3. **`Promise.all`**: This is used to run all the promises in parallel. The `await` keyword waits for all promises to resolve, and the results are destructured into `data1`, `data2`, and `data3`.
4. **Logging Results**: After all the data has been fetched, it's logged to the console.

### Output Example:

```
Data 1: { id: 1, name: "John Doe", ... }
Data 2: { id: 2, title: "Post 1", ... }
Data 3: { id: 3, message: "Welcome!" ... }
```

### Error Handling:

If any of the fetch requests fail, the `catch` block will log the error. This approach ensures that all API requests are run concurrently, and you wait for all of them to complete before logging the results.

### 18. What are the potential issues with running promises sequentially when they could run in parallel?

Running promises **sequentially** when they could run **in parallel** can lead to several potential issues, especially in terms of performance. Here are the main issues:

### 1. **Slower Execution Time**

- **Sequential Execution**: When promises are executed sequentially, each promise waits for the previous one to resolve before starting. This leads to unnecessary delays, especially when the promises are independent of each other and don't require waiting for a previous promise to complete.
- **Parallel Execution**: In contrast, when promises run in parallel, all promises start at once, and you wait for all of them to resolve simultaneously. This reduces the total execution time significantly, especially when the operations involve I/O (e.g., API requests, file reading, etc.) that don't depend on one another.

#### Example:

Suppose you have three independent asynchronous tasks (API calls, for instance) that take 2 seconds each to complete.

- **Sequential Execution**:

  - Task 1 starts, takes 2 seconds.
  - Task 2 starts after Task 1 completes, takes 2 seconds.
  - Task 3 starts after Task 2 completes, takes 2 seconds.
  - **Total time**: 6 seconds.

- **Parallel Execution**:
  - Task 1, Task 2, and Task 3 start simultaneously, each taking 2 seconds.
  - **Total time**: 2 seconds.

### 2. **Inefficient Use of Resources**

- Sequentially running independent promises can lead to underutilization of resources such as network bandwidth, CPU, and memory. If multiple requests or tasks could be handled concurrently, sequential execution wastes this potential.
- By running promises in parallel, these resources can be used more efficiently, and the system can handle more tasks in a shorter time frame.

### 3. **Increased Latency in User Experience**

- If you are making multiple network requests (e.g., API calls) in a web application, sequential execution can significantly increase the time a user has to wait for data to load. This creates a poor user experience.
- Parallel execution allows the UI to update faster, improving the perceived performance and reducing user frustration.

### 4. **No Benefit from Independent Operations**

- Sequential execution forces tasks that do not depend on each other to be executed in a specific order. If tasks are independent, running them sequentially offers no benefit other than unnecessary delay.
- Running tasks in parallel takes full advantage of the asynchronous nature of JavaScript and avoids bottlenecks where none exist.

### 5. **Missed Opportunities for Optimized Operations**

- Many modern systems, like web servers and databases, are optimized for parallel processing. Running operations sequentially can hinder the natural flow of asynchronous tasks, preventing the system from reaching its full potential.
- Tasks such as API requests, database queries, or I/O operations can often be executed in parallel, improving the performance of the entire system.

### 6. **Harder to Scale**

- If your application needs to scale to handle multiple users or requests, sequential execution can limit the throughput of your system. For example, if you have a web application making several API calls for each user, and you run them sequentially, the system may become a bottleneck as the number of concurrent users increases.
- Parallel execution allows for better scalability, as the system can handle more concurrent requests in the same amount of time.

### Example of Sequential vs. Parallel Execution:

#### Sequential Example:

```javascript
async function fetchDataSequentially() {
  const user = await fetch("https://api.example.com/user").then((response) =>
    response.json()
  );
  const posts = await fetch("https://api.example.com/posts").then((response) =>
    response.json()
  );
  const comments = await fetch("https://api.example.com/comments").then(
    (response) => response.json()
  );

  console.log(user, posts, comments);
}

fetchDataSequentially();
```

#### Parallel Example:

```javascript
async function fetchDataInParallel() {
  const [user, posts, comments] = await Promise.all([
    fetch("https://api.example.com/user").then((response) => response.json()),
    fetch("https://api.example.com/posts").then((response) => response.json()),
    fetch("https://api.example.com/comments").then((response) =>
      response.json()
    ),
  ]);

  console.log(user, posts, comments);
}

fetchDataInParallel();
```

In the parallel example, all three `fetch` calls are initiated at the same time and the `Promise.all()` method waits for all of them to resolve. This will complete in less time than the sequential approach.

### Conclusion:

The potential issues with running promises sequentially when they could run in parallel include slower execution times, inefficient resource utilization, increased latency in user experience, and missed opportunities for optimizing operations. Running independent tasks in parallel should be the default approach to improve performance and scalability. Use sequential execution only when the tasks are dependent on one another or the order of execution is crucial.

### 19. Refactor a function with multiple `await` calls into one that uses `Promise.all` for parallel execution.

Here's an example where we refactor a function with multiple `await` calls into one that uses `Promise.all` to execute the promises in parallel.

### Original Function (Sequential Execution):

```javascript
async function fetchDataSequentially() {
  const user = await fetch("https://api.example.com/user").then((response) =>
    response.json()
  );
  const posts = await fetch("https://api.example.com/posts").then((response) =>
    response.json()
  );
  const comments = await fetch("https://api.example.com/comments").then(
    (response) => response.json()
  );

  console.log(user, posts, comments);
}

fetchDataSequentially();
```

### Refactored Function (Parallel Execution Using `Promise.all`):

```javascript
async function fetchDataInParallel() {
  try {
    // Create an array of promises
    const promises = [
      fetch("https://api.example.com/user").then((response) => response.json()),
      fetch("https://api.example.com/posts").then((response) =>
        response.json()
      ),
      fetch("https://api.example.com/comments").then((response) =>
        response.json()
      ),
    ];

    // Wait for all promises to resolve using Promise.all
    const [user, posts, comments] = await Promise.all(promises);

    console.log(user, posts, comments);
  } catch (error) {
    console.error("Error fetching data:", error);
  }
}

fetchDataInParallel();
```

### Explanation:

- **Sequential Version**: Each `await` call waits for the previous promise to resolve before moving to the next one. The promises are executed one after the other.
- **Parallel Version**:
  - We create an array of promises using `map()` or directly in the `promises` array.
  - We then use `Promise.all(promises)` to run all the promises concurrently, meaning that all three `fetch` calls will be initiated at the same time.
  - Once all the promises resolve, the `await` expression waits for them to finish and destructures the results into `user`, `posts`, and `comments`.

### Benefits of Refactoring:

- **Performance Improvement**: By using `Promise.all`, the API calls are made in parallel, which should complete faster compared to sequential execution.
- **Better Resource Utilization**: Running requests in parallel makes better use of system resources like network bandwidth and CPU.

### 20. How can you use `Promise.allSettled` with `await`? Provide an example.

`Promise.allSettled()` is useful when you want to wait for all promises to settle (either fulfilled or rejected) and you want to handle all results (whether successful or failed) after all promises are completed. It returns an array of objects, each representing the outcome of a single promise, which includes the status (`"fulfilled"` or `"rejected"`) and the value or reason for rejection.

You can use `Promise.allSettled()` with `await` to wait for all promises to settle and then handle each result accordingly.

### Example:

```javascript
async function fetchDataWithAllSettled() {
  try {
    // Array of promises (some may succeed, some may fail)
    const promises = [
      fetch("https://api.example.com/user").then((response) => response.json()),
      fetch("https://api.example.com/posts").then((response) =>
        response.json()
      ),
      fetch("https://invalid-url").then((response) => response.json()), // This will fail
    ];

    // Wait for all promises to settle
    const results = await Promise.allSettled(promises);

    // Log the results of each promise
    results.forEach((result, index) => {
      if (result.status === "fulfilled") {
        console.log(`Promise ${index + 1} resolved with:`, result.value);
      } else {
        console.error(`Promise ${index + 1} rejected with:`, result.reason);
      }
    });
  } catch (error) {
    console.error("An error occurred:", error);
  }
}

fetchDataWithAllSettled();
```

### Explanation:

1. **`Promise.allSettled(promises)`**:

   - Waits for all the promises to settle, whether they are fulfilled or rejected.
   - It returns an array of result objects, where each object has:
     - `status`: Either `"fulfilled"` or `"rejected"`.
     - `value`: The resolved value if the promise was fulfilled.
     - `reason`: The rejection reason if the promise was rejected.

2. **Handling Results**:
   - The `forEach` loop iterates over each result. For each result:
     - If the status is `"fulfilled"`, we log the resolved value.
     - If the status is `"rejected"`, we log the rejection reason.

### Output:

```javascript
Promise 1 resolved with: { userData }
Promise 2 resolved with: { postsData }
Promise 3 rejected with: Error: Failed to fetch
```

### Key Points:

- **Error Handling**: Unlike `Promise.all()`, which short-circuits on the first rejection, `Promise.allSettled()` ensures that you can process all promises' results, even if some of them fail.
- **Use Cases**: It is useful when you want to wait for multiple asynchronous operations and do not want one failure to block the processing of others.

---

### **Timeouts and Races**

### 21. Write an `async` function that fetches data but times out after 3 seconds using `Promise.race`.

To implement an `async` function that fetches data and times out after 3 seconds, you can use `Promise.race()` to race between the fetch operation and a timeout. If the timeout occurs before the fetch completes, the timeout promise will reject, effectively cancelling the operation.

Here's an example:

### Example:

```javascript
async function fetchDataWithTimeout() {
  const timeout = new Promise((_, reject) =>
    setTimeout(() => reject("Request timed out after 3 seconds"), 3000)
  );

  const fetchData = fetch("https://api.example.com/data").then((response) =>
    response.json()
  );

  try {
    // Race between the fetch and timeout
    const result = await Promise.race([fetchData, timeout]);
    console.log("Data fetched:", result);
  } catch (error) {
    console.error("Error:", error);
  }
}

fetchDataWithTimeout();
```

### Explanation:

1. **Timeout Promise**: A `timeout` promise is created using `setTimeout()`. This promise rejects with a message after 3 seconds.
   - The `setTimeout()` function triggers after 3000 milliseconds (3 seconds), and the promise will reject with the message `'Request timed out after 3 seconds'`.
2. **Fetch Data**: The `fetchData` promise is created by calling `fetch()` on the API endpoint and converting the response to JSON.

3. **`Promise.race()`**: The `Promise.race()` function takes an array of promises and resolves or rejects as soon as the first promise in the array resolves or rejects. Here, it races between the `fetchData` and `timeout` promises:
   - If `fetchData` resolves first, its result is returned and logged.
   - If the `timeout` promise rejects first (i.e., the fetch takes longer than 3 seconds), the catch block is triggered, logging the timeout error.

### Key Points:

- **`Promise.race()`**: Resolves or rejects as soon as the first promise in the array settles. In this case, it helps enforce the timeout by racing the fetch against the timeout promise.
- **Error Handling**: The `try-catch` block handles both the fetch failure and the timeout rejection.

### 22. Explain how `Promise.race` can be combined with `async/await` to handle slow operations.

`Promise.race()` can be a powerful tool when combined with `async/await` to handle slow or potentially hanging asynchronous operations by introducing a timeout or fallback mechanism. Here's how it works and how you can combine it with `async/await`:

### How `Promise.race()` Works

`Promise.race()` takes an array of promises and resolves or rejects as soon as the **first** promise in the array settles (either fulfills or rejects). This means if one of the promises in the array resolves or rejects, `Promise.race()` will immediately stop and return the result of the first settled promise.

In the context of handling slow operations, you can use `Promise.race()` to race between a long-running operation (like an API call or a database query) and a timeout promise. If the operation takes too long, the timeout promise will reject, and you can handle the timeout error accordingly.

### Example: Handling Slow API Calls with Timeout Using `Promise.race`

Here's an example where we combine `Promise.race()` with `async/await` to fetch data from an API but ensure the operation times out if it takes longer than 3 seconds.

### Code Example:

```javascript
async function fetchDataWithTimeout() {
  // Create a timeout promise that rejects after 3 seconds
  const timeout = new Promise((_, reject) =>
    setTimeout(() => reject("Request timed out after 3 seconds"), 3000)
  );

  // Create a fetch data promise (this is an example URL)
  const fetchData = fetch("https://api.example.com/data").then((response) =>
    response.json()
  );

  try {
    // Use Promise.race to race between the fetch and the timeout
    const result = await Promise.race([fetchData, timeout]);
    console.log("Data fetched:", result);
  } catch (error) {
    console.error("Error:", error);
  }
}

fetchDataWithTimeout();
```

### Explanation:

1. **Timeout Promise**:

   - The `timeout` promise is created using `setTimeout()`. It will reject after 3 seconds, simulating a timeout scenario.
   - If the fetch takes longer than 3 seconds, the `timeout` promise will trigger the `catch` block.

2. **Fetch Data**:

   - The `fetchData` promise attempts to fetch data from the provided URL and convert the response into JSON.
   - If the fetch operation completes within the 3-second window, the `Promise.race()` will resolve with the fetched data.

3. **`Promise.race()`**:

   - We pass both `fetchData` and `timeout` to `Promise.race()`.
   - If `fetchData` completes before the timeout, the result is returned, and the fetch data is logged.
   - If the timeout occurs before the fetch completes (i.e., 3 seconds have passed), the `timeout` promise rejects, and the error is caught in the `catch` block.

4. **Error Handling**:
   - In the `catch` block, we handle both the fetch failure (e.g., network issues) and the timeout error (if the fetch takes too long).

### Benefits:

- **Timeout Management**: `Promise.race()` helps manage slow or hanging operations by allowing you to define a timeout that cancels the operation if it exceeds a certain duration.
- **Clean Error Handling**: By combining `Promise.race()` with `async/await`, you can write asynchronous code in a more synchronous-like manner while still handling timeouts and errors cleanly.
- **Better User Experience**: This pattern is useful for improving the user experience in web applications where long-running operations (like fetching data from APIs) can lead to delays or unresponsiveness.

### Scenario where `Promise.race` is Useful:

- **APIs with variable response times**: If your application depends on fetching data from multiple APIs, and you can't guarantee that one will respond quickly, you can use `Promise.race()` to avoid making the user wait indefinitely.
- **Background tasks with timeout**: If your app performs background tasks (e.g., file uploads, database queries) that could hang or take too long, you can use `Promise.race()` to ensure those tasks either finish on time or get canceled.

### Conclusion:

By combining `Promise.race()` with `async/await`, you can create more responsive applications by timing out slow operations and handling them in a structured, clean manner. This pattern is especially helpful in web applications where external resources (like APIs or databases) may sometimes take too long to respond.

### 23. Write a function that waits for the fastest of two promises using `async/await`.

To write a function that waits for the fastest of two promises using `async/await`, we can use `Promise.race()`. This method will return the result of the promise that settles first (either fulfilled or rejected).

### Code Example:

```javascript
async function getFastestPromise() {
  const promise1 = new Promise((resolve) =>
    setTimeout(() => resolve("Promise 1 resolved"), 2000)
  );
  const promise2 = new Promise((resolve) =>
    setTimeout(() => resolve("Promise 2 resolved"), 1000)
  );

  try {
    // Use Promise.race to wait for the fastest promise
    const fastest = await Promise.race([promise1, promise2]);
    console.log("Fastest promise result:", fastest);
  } catch (error) {
    console.error("Error:", error);
  }
}

getFastestPromise();
```

### Explanation:

1. **Promises**:

   - `promise1` resolves after 2 seconds (`2000` ms).
   - `promise2` resolves after 1 second (`1000` ms).

2. **`Promise.race()`**:

   - `Promise.race([promise1, promise2])` is used to wait for the fastest promise. Since `promise2` resolves faster (in 1 second), `Promise.race()` will return the result of `promise2` first.
   - `await` will pause execution until the fastest promise settles, and the result will be logged.

3. **Error Handling**:
   - The `try-catch` block is used to handle any errors that may occur, such as a rejected promise. In this case, we assume that both promises resolve, but it's good practice to handle potential errors.

### Output:

```javascript
Fastest promise result: Promise 2 resolved
```

### Key Points:

- **`Promise.race()`**: Resolves with the result of the first settled promise (whether fulfilled or rejected). This can be useful for operations where you want to proceed with the fastest outcome, such as loading resources, API calls, or multiple timers.
- **`async/await`**: Used here to make the code look synchronous, while still handling asynchronous operations effectively.

### 24. How would you implement a retry mechanism for a promise using `async/await`?

To implement a retry mechanism for a promise using `async/await`, you can use a loop to attempt the operation multiple times. If the promise fails (e.g., it throws an error or is rejected), it will retry the operation until it succeeds or a maximum number of retries is reached.

Here’s a simple implementation of a retry mechanism:

### Example: Retry Mechanism

```javascript
async function retryPromise(promiseFn, maxRetries = 3, delay = 1000) {
  let attempt = 0;

  while (attempt < maxRetries) {
    try {
      // Attempt to run the promise function
      const result = await promiseFn();
      console.log("Success:", result);
      return result; // Return the result if successful
    } catch (error) {
      attempt++;
      console.error(`Attempt ${attempt} failed:`, error);

      if (attempt >= maxRetries) {
        throw new Error("Max retries reached");
      }

      // Wait before retrying
      console.log(`Retrying in ${delay}ms...`);
      await new Promise((resolve) => setTimeout(resolve, delay));
    }
  }
}

// Example function that randomly fails or succeeds
async function fetchData() {
  const randomSuccess = Math.random() > 0.5; // 50% chance to succeed or fail
  if (randomSuccess) {
    return "Data fetched successfully!";
  } else {
    throw new Error("Fetch failed");
  }
}

// Use the retry mechanism to fetch data
retryPromise(fetchData, 3, 1000)
  .then((result) => console.log("Final result:", result))
  .catch((error) => console.error("Error:", error));
```

### Explanation:

1. **`retryPromise(promiseFn, maxRetries, delay)`**:

   - `promiseFn` is the function that returns a promise. This function will be retried if it fails.
   - `maxRetries` defines the maximum number of retries (default is 3).
   - `delay` is the time (in milliseconds) to wait before retrying the operation (default is 1000ms or 1 second).

2. **While Loop**:

   - The function uses a `while` loop to retry the promise a number of times (up to `maxRetries`).
   - The `attempt` variable tracks the current attempt number.

3. **`try-catch` Block**:
   - In the `try` block, the promise function (`promiseFn`) is awaited. If it resolves, the result is returned, and the function ends.
   - If the promise is rejected (i.e., an error is thrown), the `catch` block catches the error.
   - The loop increments the `attempt` count, logs the error, and checks if the maximum number of retries has been reached. If it has, it throws an error.
4. **Retry Delay**:

   - If a retry is needed, it waits for the specified `delay` using `setTimeout()` wrapped in a `Promise` to simulate the delay before retrying.

5. **`fetchData`**:
   - This is a mock function that randomly succeeds or fails. It demonstrates the retry mechanism in action.

### Example Output:

```javascript
Attempt 1 failed: Error: Fetch failed
Retrying in 1000ms...
Attempt 2 failed: Error: Fetch failed
Retrying in 1000ms...
Attempt 3 failed: Error: Fetch failed
Max retries reached
Error: Max retries reached
```

Or, if it succeeds:

```javascript
Success: Data fetched successfully!
Final result: Data fetched successfully!
```

### Key Points:

- **Retry Mechanism**: The retry mechanism will retry the promise a set number of times if it fails.
- **Error Handling**: Each failed attempt is caught, and the loop either retries or throws an error once the maximum number of retries is reached.
- **Delay Between Retries**: A delay is implemented between each retry to avoid making requests too quickly in case the error was caused by temporary conditions like network congestion or server overload.

### 25. Create a utility function that retries an async operation up to 3 times before failing.

Here's a utility function that retries an asynchronous operation up to 3 times before failing. The function will attempt the operation and, if it fails, will retry up to 3 times with a delay between each retry.

### Code Example:

```javascript
async function retryAsyncOperation(operation, maxRetries = 3, delay = 1000) {
  let attempt = 0;

  while (attempt < maxRetries) {
    try {
      // Attempt the async operation
      const result = await operation();
      return result; // Return result if successful
    } catch (error) {
      attempt++;
      console.error(`Attempt ${attempt} failed:`, error);

      if (attempt >= maxRetries) {
        throw new Error("Max retries reached. Operation failed.");
      }

      // Wait before retrying the operation
      console.log(`Retrying in ${delay}ms...`);
      await new Promise((resolve) => setTimeout(resolve, delay));
    }
  }
}

// Example async function that may fail randomly
async function fetchData() {
  const randomSuccess = Math.random() > 0.5; // 50% chance to succeed or fail
  if (randomSuccess) {
    return "Data fetched successfully!";
  } else {
    throw new Error("Fetch failed");
  }
}

// Use the utility function to retry fetchData
retryAsyncOperation(fetchData)
  .then((result) => console.log("Operation successful:", result))
  .catch((error) => console.error("Operation failed:", error));
```

### Explanation:

1. **`retryAsyncOperation`**:
   - This is the utility function that accepts an async `operation` (which is the function to be retried), a `maxRetries` value (the maximum number of retries allowed, default is 3), and a `delay` (time in milliseconds to wait before retrying, default is 1000ms or 1 second).
2. **Async Operation**:

   - The `operation` is a function that returns a promise. It can be any async function, like a network request or a database query.

3. **Retry Logic**:

   - The `while` loop continues retrying the operation until the maximum retry count (`maxRetries`) is reached.
   - If the operation succeeds, it returns the result and the function exits.
   - If the operation fails (i.e., it throws an error or the promise is rejected), the function increments the `attempt` counter and retries the operation after the specified `delay`.

4. **Error Handling**:

   - If the operation fails for all retries, an error is thrown, indicating that the maximum number of retries has been reached.

5. **`fetchData`**:
   - This is an example async function that simulates a random failure or success. It uses `Math.random()` to determine if the operation succeeds or fails.

### Example Output:

- If the operation succeeds on the first attempt:

```javascript
Operation successful: Data fetched successfully!
```

- If it fails initially and retries:

```javascript
Attempt 1 failed: Error: Fetch failed
Retrying in 1000ms...
Attempt 2 failed: Error: Fetch failed
Retrying in 1000ms...
Attempt 3 failed: Error: Fetch failed
Operation failed: Error: Max retries reached. Operation failed.
```

### Key Points:

- **Retry Logic**: The function retries the async operation up to 3 times (or the specified `maxRetries`), and waits for a specified `delay` between each retry.
- **Error Handling**: If all attempts fail, the function throws an error indicating that the operation has failed after the maximum number of retries.
- **Flexibility**: You can pass different async functions and customize the retry count and delay to fit your needs.

---

### **Error Propagation and Debugging**

### 26. Write an `async` function that intentionally throws an error and logs it using `try-catch`.

Here’s an example of an `async` function that intentionally throws an error and logs it using a `try-catch` block:

### Code Example:

```javascript
async function throwErrorExample() {
  try {
    // Intentionally throw an error
    throw new Error("Something went wrong!");
  } catch (error) {
    // Catch and log the error
    console.error("Caught an error:", error.message);
  }
}

// Call the function to see the result
throwErrorExample();
```

### Explanation:

1. **`throw new Error('Something went wrong!')`**:

   - This line of code intentionally throws an error with the message `'Something went wrong!'`.

2. **`try-catch` Block**:
   - The `try` block contains the code that may throw an error (in this case, the `throw new Error` statement).
   - The `catch` block catches the error thrown by the `throw` statement. The `error.message` is logged to the console, showing the error message.

### Output:

```javascript
Caught an error: Something went wrong!
```

### Key Points:

- **Error Handling**: The `try-catch` block is used to catch and handle any errors that occur in the `try` block.
- **Intentionally Throwing Errors**: This can be useful in situations where you want to simulate error scenarios or validate error handling in your code.

### 27. How does the stack trace of an error in `async/await` compare to that in promises?

The stack trace of an error in `async/await` and in promises can behave differently, primarily due to how JavaScript handles asynchronous operations and the timing of stack unwinding.

Here’s a comparison of stack traces between `async/await` and promises:

### 1. **Stack Trace with Promises**

When using promises, errors are caught and logged after the promise is rejected. If you throw an error inside a `.then()` or `.catch()` handler, the stack trace will only show the error from that handler's execution context, not the context where the error was initially thrown.

#### Example with Promises:

```javascript
function throwErrorWithPromise() {
  return new Promise((resolve, reject) => {
    // Simulate an error
    throw new Error("Error in Promise");
  });
}

throwErrorWithPromise().catch((error) => {
  console.error(error.stack);
});
```

### Output:

```
Error: Error in Promise
    at throwErrorWithPromise (index.js:4:11)
    at new Promise (<anonymous>)
    at index.js:8:1
```

### Explanation:

- The error is thrown inside the `Promise` constructor, but the stack trace starts from where the `catch` block handles the error, not from where the promise is created. This means it misses the exact location where the error was initially thrown.

### 2. **Stack Trace with `async/await`**

When using `async/await`, the stack trace behaves similarly to how synchronous errors are handled. The stack trace will reflect the exact location where the error is thrown, even if it is inside an asynchronous function.

#### Example with `async/await`:

```javascript
async function throwErrorWithAsync() {
  // Simulate an error
  throw new Error("Error in Async");
}

async function testAsyncError() {
  try {
    await throwErrorWithAsync();
  } catch (error) {
    console.error(error.stack);
  }
}

testAsyncError();
```

### Output:

```
Error: Error in Async
    at throwErrorWithAsync (index.js:3:9)
    at testAsyncError (index.js:7:9)
    at index.js:11:1
```

### Explanation:

- The stack trace with `async/await` clearly shows that the error was thrown in the `throwErrorWithAsync` function, even though it’s inside an asynchronous operation.
- The error stack trace reflects the exact line where the error occurred and shows the chain of function calls leading to the error (in this case, `testAsyncError` and `index.js`).

### Key Differences Between Promises and `async/await` Stack Traces:

- **Promises**: The stack trace will not directly point to the place where the error was thrown if it's inside a promise chain. Instead, it will start from the `.catch()` handler, which can make the stack trace harder to trace back to the original error location.
- **`async/await`**: The stack trace behaves more intuitively, showing the exact line and function where the error occurred, even for asynchronous errors. The error is handled synchronously in the `try-catch` block, making it easier to trace.

### Why This Happens:

- **Promise Rejection**: In promises, the error is propagated asynchronously. The stack trace may not capture the exact location of the error because the error occurs inside an event loop cycle, and JavaScript “forgets” the synchronous call stack once the promise is invoked and rejected.

- **`async/await`**: Errors thrown inside an `async` function are caught by the `try-catch` block in a synchronous manner. This allows the stack trace to preserve the context of the error, showing the exact function where the error occurred.

### Conclusion:

- **`async/await`** provides clearer, more accurate stack traces that reflect the original error source.
- **Promises** may have less intuitive stack traces due to the asynchronous nature of promise handling, which can obscure the original source of the error.

### 28. What happens if you forget to wrap an `await` call in `try-catch`?

If you forget to wrap an `await` call in a `try-catch` block, any error that occurs within the `await` operation will be unhandled, causing the promise to reject and potentially leading to unhandled promise rejections. This can cause the program to terminate (in Node.js environments) or result in unexpected behavior in the browser.

### Key Points:

- **Uncaught Errors**: If you `await` a promise and the promise rejects, and you do not handle the error, it will cause an unhandled promise rejection.
- **Unhandled Promise Rejections**: In modern JavaScript environments (both browsers and Node.js), unhandled promise rejections will typically log a warning and can even terminate the process (in Node.js, as of version 15, unhandled rejections will terminate the process by default).

### Example of Forgotten `try-catch` in `async/await`:

```javascript
async function fetchData() {
  const response = await fetch("https://nonexistent-api.com"); // This will fail
  const data = await response.json();
  return data;
}

fetchData();
```

### What Happens Here:

- The `fetch` call will likely fail because `'https://nonexistent-api.com'` does not exist, and it will return a rejected promise.
- Since there is no `try-catch` around the `await` call, the error is unhandled.
- In **Node.js**, this will trigger an unhandled promise rejection warning.
- In **browser environments**, the error will be logged to the console.

### Output:

- **In the browser**: The browser will log the error in the console but will not crash the application.

  Example:

  ```
  Unhandled promise rejection: TypeError: Failed to fetch
  ```

- **In Node.js (v15 and above)**: Unhandled promise rejections will cause the process to exit.

  Example:

  ```
  (node:1234) UnhandledPromiseRejectionWarning: FetchError: request to https://nonexistent-api.com failed
  (node:1234) UnhandledPromiseRejectionWarning: Unhandled promise rejection. This error originated either by throwing inside of an async function without a catch block, or by a promise rejection inside a `then()` callback.
  (node:1234) DeprecationWarning: Unhandled promise rejections are deprecated. In future versions, the Node.js process will terminate with a non-zero exit code.
  ```

### Proper Error Handling with `try-catch`:

To properly handle errors and prevent unhandled promise rejections, you should always wrap `await` calls in a `try-catch` block:

```javascript
async function fetchData() {
  try {
    const response = await fetch("https://nonexistent-api.com");
    const data = await response.json();
    return data;
  } catch (error) {
    console.error("Error fetching data:", error);
  }
}

fetchData();
```

### In this case:

- **If an error occurs** (such as a network failure or a rejected promise), it is caught by the `catch` block.
- The error will be logged, and the program will continue running normally, preventing any unhandled promise rejection warnings.

### Conclusion:

- **Without `try-catch`**: Unhandled promise rejections can lead to warnings, crashes (in Node.js), or unexpected behavior.
- **With `try-catch`**: Errors are handled gracefully, and the program can continue running without issues, and you can log or process the error accordingly.

### 29. Can you propagate errors thrown inside an `async` function to the caller? Show an example.

Yes, you can propagate errors thrown inside an `async` function to the caller. When an error is thrown inside an `async` function, it returns a rejected promise, and you can propagate this error to the caller by allowing the rejection to bubble up. The caller can then handle the error using `try-catch` or `.catch()`.

Here’s an example of how to propagate an error from an `async` function to the caller:

### Example 1: Propagating Errors Using `async/await`

```javascript
async function fetchData() {
  // Simulating an error
  throw new Error("Something went wrong in fetchData");
}

async function caller() {
  try {
    await fetchData();
  } catch (error) {
    console.error("Error caught in caller:", error.message);
    // Propagate the error further
    throw error; // Re-throwing the error to the caller of `caller`
  }
}

async function main() {
  try {
    await caller(); // This will propagate the error to here
  } catch (error) {
    console.error("Error caught in main:", error.message);
  }
}

main();
```

### Output:

```
Error caught in caller: Something went wrong in fetchData
Error caught in main: Something went wrong in fetchData
```

### Explanation:

1. **`fetchData()`**: This function throws an error (`"Something went wrong in fetchData"`).
2. **`caller()`**: It calls `fetchData()` inside a `try-catch` block. If an error occurs in `fetchData()`, it is caught, and we re-throw the error using `throw error;` to propagate it to the caller.
3. **`main()`**: Calls `caller()`. The error is propagated up from `fetchData` → `caller` → `main`. The `try-catch` in `main()` catches the re-thrown error.

### Example 2: Propagating Errors Using `.catch()`

You can also propagate errors using promise chains with `.catch()`.

```javascript
async function fetchData() {
  throw new Error("Something went wrong in fetchData");
}

function caller() {
  return fetchData().catch((error) => {
    console.error("Error caught in caller:", error.message);
    // Propagate the error further by returning the rejected promise
    return Promise.reject(error); // Re-throwing the error
  });
}

function main() {
  caller().catch((error) => {
    console.error("Error caught in main:", error.message);
  });
}

main();
```

### Output:

```
Error caught in caller: Something went wrong in fetchData
Error caught in main: Something went wrong in fetchData
```

### Explanation:

- In this version, `caller()` catches the error from `fetchData()` using `.catch()` and rethrows it by returning `Promise.reject(error)`, propagating the error to the next `.catch()` in the chain (`main()`).

### Conclusion:

- **Error Propagation**: You can propagate errors from an `async` function by either throwing the error inside a `try-catch` block or using `.catch()` to rethrow the error.
- **Caller Handling**: The caller can handle the propagated error using another `try-catch` block or `.catch()` to catch and manage the error accordingly.

### 30. Write a function that calls an `async` function and catches errors propagated from it.

Here’s an example where a function calls an `async` function and catches errors propagated from it:

### Example:

```javascript
// An async function that throws an error
async function fetchData() {
  throw new Error("Something went wrong in fetchData");
}

// A function that calls the async function and catches the propagated error
async function caller() {
  try {
    await fetchData(); // Calling the async function that throws an error
  } catch (error) {
    console.error("Error caught in caller:", error.message); // Catching the error here
  }
}

// Calling the function that handles the error
caller();
```

### Output:

```
Error caught in caller: Something went wrong in fetchData
```

### Explanation:

- **`fetchData()`**: This `async` function throws an error with the message `"Something went wrong in fetchData"`.
- **`caller()`**: This function calls `fetchData()` and handles any errors that it propagates. The `await` keyword waits for the promise returned by `fetchData()`. If the promise is rejected, the error is caught in the `catch` block.
- **Error Handling**: The error is caught in the `catch` block inside the `caller()` function and logged to the console with the message `"Error caught in caller: Something went wrong in fetchData"`.

### Conclusion:

- The error thrown by the `async` function (`fetchData()`) is propagated to the caller (`caller()`), where it is caught and handled using a `try-catch` block.

---

### **Real-World Scenarios**

### 31. Write an `async` function for a user authentication workflow with the following steps:

    - Verify the user credentials.
    - Fetch user profile data if credentials are valid.
    - Log an error if credentials are invalid.

Here’s an example of an `async` function implementing a user authentication workflow with the specified steps:

### Example: User Authentication Workflow

```javascript
// Simulate verifying user credentials
async function verifyCredentials(username, password) {
  // Simulating checking the credentials
  if (username === "user" && password === "password123") {
    return true; // Credentials are valid
  } else {
    throw new Error("Invalid credentials"); // Invalid credentials
  }
}

// Simulate fetching the user profile
async function fetchUserProfile(username) {
  // Simulating fetching user profile data from a database or API
  const profiles = {
    user: { name: "John Doe", age: 30, email: "johndoe@example.com" },
    admin: { name: "Admin User", age: 35, email: "admin@example.com" },
  };
  return profiles[username];
}

// The main authentication function that performs the workflow
async function authenticateUser(username, password) {
  try {
    // Step 1: Verify the user credentials
    const isValid = await verifyCredentials(username, password);
    if (!isValid) {
      console.error("Authentication failed");
      return;
    }

    // Step 2: Fetch user profile if credentials are valid
    const userProfile = await fetchUserProfile(username);
    console.log("User authenticated successfully:", userProfile);
  } catch (error) {
    // Step 3: Log an error if credentials are invalid
    console.error("Authentication error:", error.message);
  }
}

// Example usage
authenticateUser("user", "password123"); // Valid credentials
authenticateUser("user", "wrongpassword"); // Invalid credentials
```

### Output:

#### For valid credentials (`username = "user"`, `password = "password123"`):

```
User authenticated successfully: { name: 'John Doe', age: 30, email: 'johndoe@example.com' }
```

#### For invalid credentials (`username = "user"`, `password = "wrongpassword"`):

```
Authentication error: Invalid credentials
```

### Explanation:

1. **`verifyCredentials(username, password)`**: This function checks if the username and password match a predefined set of credentials. If they match, it returns `true`. If they don't match, it throws an error with the message `"Invalid credentials"`.
2. **`fetchUserProfile(username)`**: This function simulates fetching user profile data for a valid user (stored in a simple object for this example). It returns the profile data for the given username.
3. **`authenticateUser(username, password)`**: This is the main function that calls `verifyCredentials()` to check if the user’s credentials are valid. If the credentials are valid, it proceeds to call `fetchUserProfile()` to retrieve the user’s profile. If there’s an error at any point (e.g., invalid credentials), it is caught by the `catch` block and logged.
4. **Error Handling**: The `catch` block catches errors thrown by either `verifyCredentials` (if credentials are invalid) or any other part of the code and logs the error message.

### Conclusion:

- The function successfully verifies the user’s credentials, fetches the user’s profile if valid, and handles errors if the credentials are invalid, logging an appropriate message.

### 32. Implement an `async` function that reads data from a file, processes it, and writes it back to another file.

To implement an `async` function that reads data from a file, processes it, and writes it back to another file, we can use the Node.js `fs` module, which provides asynchronous methods for working with the file system. Specifically, we'll use `fs.promises.readFile` to read the file, perform some processing on the data, and then use `fs.promises.writeFile` to write the processed data back to a different file.

Here’s an example implementation:

### Example: Reading, Processing, and Writing Data to Files

```javascript
const fs = require("fs").promises; // Use the promise-based version of fs module

// An async function that reads, processes, and writes data to files
async function processData(inputFile, outputFile) {
  try {
    // Step 1: Read data from the input file
    const data = await fs.readFile(inputFile, "utf8"); // Read file content as a string

    // Step 2: Process the data (For this example, we'll simply convert it to uppercase)
    const processedData = data.toUpperCase(); // Example processing

    // Step 3: Write the processed data to the output file
    await fs.writeFile(outputFile, processedData, "utf8"); // Write to the output file
    console.log(`Data successfully written to ${outputFile}`);
  } catch (error) {
    // Catch and log any errors that occur during file reading or writing
    console.error("Error processing file:", error.message);
  }
}

// Example usage: Read data from 'input.txt' and write the processed data to 'output.txt'
processData("input.txt", "output.txt");
```

### Explanation:

1. **`fs.promises.readFile(inputFile, 'utf8')`**: This reads the contents of `inputFile` asynchronously. The `'utf8'` encoding ensures that the data is returned as a string. If you omit the encoding, the data will be returned as a `Buffer`.
2. **Data Processing**: In this example, we simply convert the data to uppercase using `data.toUpperCase()`. You can replace this with any processing logic, such as parsing JSON, transforming data, etc.
3. **`fs.promises.writeFile(outputFile, processedData, 'utf8')`**: This writes the processed data to `outputFile` asynchronously. The `'utf8'` encoding ensures the output is written as a text file. If the file doesn't exist, it will be created; if it exists, it will be overwritten.
4. **Error Handling**: We wrap the entire process in a `try-catch` block to catch any errors that may occur during reading, processing, or writing the file. Errors might arise if the input file doesn't exist or if there are permission issues.

### Example Scenario:

If `input.txt` contains the following text:

```
Hello, world! This is a test file.
```

The `processData` function would process this text and write the following to `output.txt`:

```
HELLO, WORLD! THIS IS A TEST FILE.
```

### Conclusion:

- **Async File Operations**: Using `fs.promises.readFile` and `fs.promises.writeFile` with `async/await` allows for non-blocking asynchronous file handling.
- **Error Handling**: The function includes error handling to deal with potential issues, such as missing files or permission problems.
- **Data Processing**: The data is processed after being read, which can be customized to suit your specific needs.

### 33. Write an `async` function that simulates a file download, but if it fails, retries the download three times.

To simulate a file download in an `async` function and retry the download up to three times if it fails, we can implement a retry mechanism using a `for` loop and `try-catch` blocks. In this scenario, we will simulate the download with a random chance of failure to demonstrate how retries would work.

Here’s how you can implement this:

### Example: Simulating a File Download with Retry Logic

```javascript
// Simulating a download function
async function downloadFile(fileUrl) {
  // Simulate a failure with a random chance
  const randomFailureChance = Math.random(); // Random number between 0 and 1
  if (randomFailureChance < 0.5) {
    // Simulating a failed download (50% chance)
    throw new Error(`Failed to download file from ${fileUrl}`);
  } else {
    // Simulating a successful download
    console.log(`Successfully downloaded file from ${fileUrl}`);
  }
}

// Function to attempt the download and retry up to 3 times on failure
async function downloadWithRetry(fileUrl, retries = 3) {
  let attempt = 0;

  while (attempt < retries) {
    try {
      // Attempt to download the file
      await downloadFile(fileUrl);
      console.log("File download complete.");
      return; // Exit the function if the download is successful
    } catch (error) {
      attempt++; // Increment the attempt counter
      console.error(`Attempt ${attempt} failed: ${error.message}`);

      // If we have reached the maximum number of retries, throw the error
      if (attempt >= retries) {
        console.error("Max retries reached. Download failed.");
        throw error; // Rethrow the error after retries are exhausted
      } else {
        console.log(`Retrying download... (${attempt}/${retries})`);
      }
    }
  }
}

// Example usage
downloadWithRetry("https://example.com/file.zip")
  .then(() => console.log("Download completed successfully."))
  .catch((error) => console.log("Final failure:", error.message));
```

### Explanation:

1. **`downloadFile(fileUrl)`**: This function simulates the process of downloading a file. It has a 50% chance of failing (using `Math.random()` to generate a random failure chance) and throws an error if the download fails.
2. **`downloadWithRetry(fileUrl, retries = 3)`**: This function manages the retry logic. It will attempt to download the file up to `retries` times (default is 3). If a failure occurs, it catches the error and retries the download. If all retry attempts fail, it logs an error and throws the error.
3. **Retry Logic**: A `while` loop is used to attempt the download up to the specified number of retries. If the download fails on all attempts, the function will throw an error after the final retry.
4. **Error Handling**: The `catch` block handles errors, logging the failure for each attempt, and retrying the download until the retry limit is reached.

### Example Output:

- If the download succeeds on the first attempt:

```
Successfully downloaded file from https://example.com/file.zip
File download complete.
Download completed successfully.
```

- If the download fails and retries are needed:

```
Attempt 1 failed: Failed to download file from https://example.com/file.zip
Retrying download... (1/3)
Attempt 2 failed: Failed to download file from https://example.com/file.zip
Retrying download... (2/3)
Attempt 3 failed: Failed to download file from https://example.com/file.zip
Max retries reached. Download failed.
Final failure: Failed to download file from https://example.com/file.zip
```

### Conclusion:

- **Retry Mechanism**: The function tries to download the file up to 3 times (or a specified number of retries) and logs the result for each attempt.
- **Asynchronous Workflow**: The `async` and `await` syntax is used to handle the asynchronous download process, allowing retries without blocking the execution.

### 34. Create an `async` function to fetch data from an API and use fallback data if the API is unavailable.

Here’s an example of an `async` function that fetches data from an API and falls back to default data if the API is unavailable or if an error occurs:

### Example: Fetching Data with Fallback

```javascript
// Simulating a fetch function to get data from an API
async function fetchDataFromApi(url) {
  // Simulate a random failure for demonstration purposes
  const randomFailureChance = Math.random();
  if (randomFailureChance < 0.5) {
    // Simulating a failed API request
    throw new Error(`Failed to fetch data from ${url}`);
  }
  // Simulating successful data fetching
  return { data: "Data fetched from the API" };
}

// Fallback data in case the API is unavailable
const fallbackData = { data: "This is fallback data" };

// Async function that tries to fetch data from the API and uses fallback data if the API fails
async function getData(url) {
  try {
    // Attempt to fetch data from the API
    const data = await fetchDataFromApi(url);
    console.log("Data fetched from API:", data);
    return data;
  } catch (error) {
    // If fetching from the API fails, use the fallback data
    console.error("Error fetching data, using fallback data:", error.message);
    return fallbackData;
  }
}

// Example usage
getData("https://example.com/api")
  .then((data) => console.log("Final data:", data))
  .catch((error) => console.log("Final failure:", error.message));
```

### Explanation:

1. **`fetchDataFromApi(url)`**: This function simulates an API call that might fail. We use a random chance (`Math.random()`) to simulate a failure condition (with a 50% chance). If it fails, an error is thrown.
2. **`fallbackData`**: This object represents the fallback data that will be used if the API call fails.
3. **`getData(url)`**: This is the main `async` function. It tries to fetch data from the API using `fetchDataFromApi()`. If the API call fails (catches an error), it logs the error and returns the fallback data instead.
4. **Error Handling**: If an error occurs during the API call, the `catch` block handles it and provides fallback data. The error message is logged for debugging purposes.

### Example Output:

- If the API request is successful:

```
Data fetched from API: { data: 'Data fetched from the API' }
Final data: { data: 'Data fetched from the API' }
```

- If the API request fails and fallback data is used:

```
Error fetching data, using fallback data: Failed to fetch data from https://example.com/api
Final data: { data: 'This is fallback data' }
```

### Conclusion:

- **Async Function with Fallback**: The function first tries to fetch data from the API. If that fails (due to an error), it falls back to using default data.
- **Error Handling**: The `try-catch` block handles any errors that occur during the API call and ensures that the program continues by using fallback data.

### 35. Write a `getUserDashboard` function that fetches posts, comments, and user info simultaneously.

To implement the `getUserDashboard` function that fetches posts, comments, and user info simultaneously, you can use `Promise.all` in combination with `async/await` to run the API calls in parallel. This approach allows for concurrent fetching, improving performance by waiting for all three requests to complete at the same time.

Here’s how you can write the function:

### Example: `getUserDashboard` Function

```javascript
// Simulate API calls that fetch posts, comments, and user info
async function fetchPosts() {
  return new Promise((resolve) => {
    setTimeout(() => resolve({ posts: ["Post 1", "Post 2", "Post 3"] }), 1000); // Simulated delay
  });
}

async function fetchComments() {
  return new Promise((resolve) => {
    setTimeout(
      () => resolve({ comments: ["Comment 1", "Comment 2", "Comment 3"] }),
      1500
    ); // Simulated delay
  });
}

async function fetchUserInfo() {
  return new Promise((resolve) => {
    setTimeout(() => resolve({ user: { name: "John Doe", age: 30 } }), 500); // Simulated delay
  });
}

// Main function to fetch all data simultaneously
async function getUserDashboard() {
  try {
    // Fetch all data in parallel using Promise.all
    const [posts, comments, userInfo] = await Promise.all([
      fetchPosts(),
      fetchComments(),
      fetchUserInfo(),
    ]);

    // Combine and log the results
    console.log("User Info:", userInfo);
    console.log("Posts:", posts);
    console.log("Comments:", comments);

    return { userInfo, posts, comments };
  } catch (error) {
    // Handle any errors that occur during the API requests
    console.error("Error fetching dashboard data:", error);
    throw error;
  }
}

// Example usage
getUserDashboard()
  .then((dashboard) => {
    console.log("Dashboard:", dashboard);
  })
  .catch((error) => {
    console.log("Error:", error.message);
  });
```

### Explanation:

1. **Simulated API Calls**:
   - `fetchPosts()`, `fetchComments()`, and `fetchUserInfo()` are async functions that simulate fetching posts, comments, and user info. They each return a `Promise` that resolves after a specified delay to mimic real API requests.
2. **`Promise.all`**:

   - The `getUserDashboard` function uses `Promise.all` to run all three fetch functions concurrently. This allows all three API requests to execute in parallel, reducing the overall waiting time.
   - `Promise.all` returns an array of results, which we destructure into `posts`, `comments`, and `userInfo` using array destructuring.

3. **Error Handling**:

   - If any of the API requests fail, the `catch` block will log the error message and rethrow it. This ensures that the error is propagated properly.

4. **Example Usage**:
   - When `getUserDashboard` is called, it will fetch the posts, comments, and user info in parallel and log the results.

### Example Output:

```
User Info: { user: { name: 'John Doe', age: 30 } }
Posts: { posts: ['Post 1', 'Post 2', 'Post 3'] }
Comments: { comments: ['Comment 1', 'Comment 2', 'Comment 3'] }
Dashboard: { userInfo: { user: { name: 'John Doe', age: 30 } }, posts: { posts: ['Post 1', 'Post 2', 'Post 3'] }, comments: { comments: ['Comment 1', 'Comment 2', 'Comment 3'] } }
```

### Conclusion:

- **Parallel Execution**: `Promise.all` allows you to fetch the data (posts, comments, and user info) concurrently, reducing the time required to fetch all three pieces of data.
- **Error Handling**: If any request fails, the error is caught and logged, ensuring robustness.
- **Improved Performance**: By fetching the data concurrently, the overall execution time is minimized.

---

### **Advanced Topics**

### 36. Can an `async` function return a value other than a promise? Why or why not?

No, an `async` function **always returns a promise**, regardless of whether you explicitly return a promise or not. Even if you return a non-promise value (like a primitive value or an object), JavaScript will automatically wrap that value in a resolved promise.

### Explanation:

When you define a function as `async`, it implies that the function will always return a `Promise`. If you return a non-promise value, JavaScript will automatically convert that value into a resolved promise. This ensures that the function behaves consistently with asynchronous operations, even if it is not explicitly using promises or awaiting an asynchronous task.

### Example:

#### Returning a non-promise value (e.g., a number):

```javascript
async function getNumber() {
  return 42;
}

getNumber().then((result) => {
  console.log(result); // 42
});
```

In this example, `getNumber()` returns the value `42`, but JavaScript automatically wraps it in a resolved promise. So, `getNumber()` will return a `Promise` that resolves to `42`.

#### Returning a promise explicitly:

```javascript
async function getData() {
  return Promise.resolve("Data from API");
}

getData().then((result) => {
  console.log(result); // "Data from API"
});
```

In this case, `getData()` explicitly returns a resolved promise, and the function behaves as expected.

### Key Points:

- **Promise Wrapper**: An `async` function always returns a `Promise`, even if you return a regular value (non-promise).
- **Automatic Wrapping**: If a non-promise value is returned from an `async` function, it is automatically wrapped in a resolved `Promise`.

Thus, **whether you return a promise or not, the `async` function will always return a promise**, ensuring consistency in how asynchronous results are handled.

### 37. Write an `async` function that demonstrates how `await` pauses execution but doesn’t block the thread.

Here’s an example of how the `await` keyword pauses the execution of an `async` function without blocking the main thread. The `await` only pauses the execution of the `async` function it’s in, allowing other tasks (such as UI updates or event handling) to continue executing on the main thread.

### Example: Demonstrating `await` Pausing Execution Without Blocking the Thread

```javascript
// Simulate an async operation (like fetching data)
function simulateAsyncTask(seconds) {
  return new Promise((resolve) => {
    setTimeout(() => {
      resolve(`Task completed after ${seconds} second(s)`);
    }, seconds * 1000);
  });
}

// Async function to demonstrate how await works
async function demonstrateAwait() {
  console.log("Start of the async function");

  // The execution pauses here, but the thread isn't blocked
  const result = await simulateAsyncTask(2);
  console.log(result); // Logs after 2 seconds

  console.log("End of the async function");
}

// Call the async function
demonstrateAwait();

console.log("This logs immediately while the async function waits");
```

### Explanation:

1. **`simulateAsyncTask(seconds)`**: This function simulates an asynchronous task that resolves after a given number of seconds. It uses `setTimeout` to delay the resolution of the promise.

2. **`demonstrateAwait()`**: This is an `async` function that demonstrates how `await` works. Inside the function:

   - The `await simulateAsyncTask(2)` pauses the execution of the function for 2 seconds.
   - While `await` is waiting, it doesn't block the main thread. Other code, such as `console.log("This logs immediately...")`, can still run.

3. **Output**:
   - `"Start of the async function"` is logged immediately when the function is called.
   - `"This logs immediately while the async function waits"` is logged while the function is waiting for the promise to resolve.
   - After 2 seconds, the result of `simulateAsyncTask(2)` is logged: `"Task completed after 2 second(s)"`.
   - Finally, `"End of the async function"` is logged.

### Example Output:

```
Start of the async function
This logs immediately while the async function waits
Task completed after 2 second(s)
End of the async function
```

### Key Points:

- **Pauses Execution of `async` Function**: The `await` keyword pauses the execution of the `demonstrateAwait` function while waiting for the `simulateAsyncTask` promise to resolve.
- **Doesn't Block the Thread**: While `await` pauses the execution inside the `async` function, it doesn’t block the main JavaScript thread. Other operations, like logging or UI updates, can continue.

### 38. Explain the role of the event loop in executing `async/await` code.

The **event loop** plays a crucial role in executing JavaScript code, including code that uses `async/await`. JavaScript, as a single-threaded language, relies on the event loop to handle asynchronous operations without blocking the main thread. The event loop ensures that tasks such as I/O operations, timers, and asynchronous code are executed in a non-blocking manner, allowing other code to run concurrently.

### How the Event Loop Works with `async/await`

When you use `async/await`, the event loop helps manage the asynchronous execution flow by managing promises and the code that follows the `await` statement.

### Steps Involved in `async/await` Execution:

1. **Async Function Invocation**:

   - When an `async` function is called, it immediately returns a **promise**, but the function doesn't start executing its body right away.
   - The code inside the `async` function is placed in the **microtask queue** for execution after the current synchronous code finishes executing.

2. **Encountering `await`**:

   - When the `await` keyword is used, JavaScript pauses the execution of the `async` function, but it does **not block the main thread**.
   - The `await` expression waits for the resolution of the promise.
   - While the promise is pending, the event loop is free to execute other tasks (such as handling UI events or executing other JavaScript code).

3. **Promise Resolution**:

   - When the promise resolves (either fulfilled or rejected), the corresponding `.then()` or `catch()` callback is placed in the **microtask queue**.
   - The event loop ensures that all microtasks are executed before it moves on to the next task in the macro task queue (like UI rendering or I/O).

4. **Resuming Execution**:
   - Once the promise is resolved and all previous synchronous code has been executed, the event loop picks up the callback from the microtask queue and resumes the execution of the `async` function after the `await`.
   - The result of the awaited promise is returned to the `async` function, and the function continues executing from where it left off.

### Example to Illustrate the Event Loop:

```javascript
// Simulating an async operation with a delay
function simulateAsyncTask(seconds) {
  return new Promise((resolve) => {
    setTimeout(() => {
      resolve(`Task completed after ${seconds} second(s)`);
    }, seconds * 1000);
  });
}

async function example() {
  console.log("Start");

  const result1 = await simulateAsyncTask(2); // Pauses here for 2 seconds
  console.log(result1); // Logs after 2 seconds

  const result2 = await simulateAsyncTask(1); // Pauses here for 1 second
  console.log(result2); // Logs after 1 second

  console.log("End");
}

example();
console.log("This logs immediately while waiting for async tasks.");
```

### Event Loop Breakdown:

1. **"Start"** is logged immediately because it's part of the synchronous code.
2. The `await simulateAsyncTask(2)` is encountered, and the function is paused.
3. The `simulateAsyncTask` creates a promise that resolves after 2 seconds, and the promise is added to the **microtask queue**.
4. While the function is paused waiting for the promise, `"This logs immediately while waiting for async tasks."` is logged because it is outside the `async` function.
5. After 2 seconds, the promise is resolved, and the callback is executed from the **microtask queue**, logging `Task completed after 2 second(s)`.
6. The function proceeds to `await simulateAsyncTask(1)`, pauses again, and the process repeats.
7. Finally, `"End"` is logged when both promises have resolved.

### Example Output:

```
Start
This logs immediately while waiting for async tasks.
Task completed after 2 second(s)
Task completed after 1 second(s)
End
```

### Key Points About the Event Loop:

- **Microtask Queue**: When an `async` function encounters `await`, the promise is resolved asynchronously, and the callback to resume the function is placed in the microtask queue.
- **Non-blocking**: The event loop doesn't block while waiting for a promise to resolve. It allows the execution of other synchronous tasks (like logging).
- **Microtasks vs. Macrotasks**: After each task in the **macrotask queue** (such as I/O events or timers) is completed, the event loop checks the **microtask queue** and executes any pending microtasks (like promise resolution) before continuing.

### Conclusion:

The event loop enables the asynchronous behavior of `async/await` by managing promise resolution in the microtask queue and ensuring that the JavaScript runtime remains non-blocking. It allows asynchronous code to run concurrently while ensuring the synchronous flow continues without interruption.

### 39. Can you use `await` with non-promise values? What happens if you do?

Yes, you can use `await` with non-promise values, but the behavior is slightly different than when used with a promise.

### Behavior with Non-Promise Values:

When you use `await` with a **non-promise** value (such as a primitive value or an object), JavaScript **wraps** the value in a resolved `Promise`. This means that `await` will immediately return the value inside a resolved promise.

- If the value is **not a promise**, it will behave as though it was a promise that immediately resolves with that value.
- If the value is **already a promise**, `await` will wait for the promise to resolve or reject.

### Example: Using `await` with Non-Promise Values

```javascript
async function example() {
  const number = 42;
  const text = "Hello, world!";

  // Awaiting non-promise values
  const result1 = await number; // Non-promise value (number)
  const result2 = await text; // Non-promise value (string)

  console.log(result1); // 42
  console.log(result2); // "Hello, world!"
}

example();
```

### Explanation:

1. **`number`** and **`text`** are non-promise values (primitive types: `42` and `"Hello, world!"`).
2. When `await` is applied to them, JavaScript wraps these values in resolved promises, meaning:
   - `await number` behaves as if it were `await Promise.resolve(42)`.
   - `await text` behaves as if it were `await Promise.resolve("Hello, world!")`.
3. The values are immediately resolved, so the `await` operation completes quickly.

### Key Points:

- **Automatic Wrapping**: If the value is not a promise, `await` automatically wraps it in a resolved promise, which makes it behave like a promise.
- **No Effect on Non-Promises**: For non-promise values, `await` essentially does nothing except converting the value into a resolved promise, which is immediately resolved with that value.

### Example with `await` on Promises:

To compare, if you use `await` with a promise, it will pause until the promise is resolved:

```javascript
async function fetchData() {
  const promise = new Promise((resolve) => {
    setTimeout(() => resolve("Data fetched!"), 2000);
  });

  const result = await promise; // Pauses until the promise resolves
  console.log(result); // "Data fetched!" after 2 seconds
}

fetchData();
```

### Summary:

- **With non-promise values**, `await` resolves immediately, wrapping the value in a resolved promise.
- **With promises**, `await` pauses execution until the promise resolves or rejects.

### 40. Write an `async` generator function that yields values from a sequence of promises.

An `async` generator function allows you to use the `await` keyword within the generator and yield asynchronous values one at a time. This is useful when you're working with a sequence of asynchronous operations that produce values over time, such as fetching data from multiple sources.

### Example: `async` Generator Function that Yields Values from a Sequence of Promises

```javascript
// Simulating an async task that resolves after a given delay
function simulateAsyncTask(value, delay) {
  return new Promise((resolve) => {
    setTimeout(() => {
      resolve(value);
    }, delay);
  });
}

// Async generator function
async function* fetchAsyncData() {
  const data1 = await simulateAsyncTask("Data 1", 1000); // Resolves after 1 second
  yield data1;

  const data2 = await simulateAsyncTask("Data 2", 1500); // Resolves after 1.5 seconds
  yield data2;

  const data3 = await simulateAsyncTask("Data 3", 2000); // Resolves after 2 seconds
  yield data3;
}

// Using the async generator function
(async () => {
  for await (const data of fetchAsyncData()) {
    console.log(data); // Logs the yielded values one by one
  }
})();
```

### Explanation:

1. **`simulateAsyncTask`**: This function simulates an asynchronous task (such as fetching data) that resolves after a specified delay.
2. **`fetchAsyncData`**: This is an `async` generator function:
   - It uses `await` to wait for each promise to resolve.
   - Each resolved value is yielded one by one, allowing asynchronous iteration.
3. **For-await-of Loop**: The `for await...of` loop is used to iterate over the async generator and log each value as it is yielded.

### Example Output:

```
Data 1
Data 2
Data 3
```

### Key Points:

- **Async Generators**: The `async function*` syntax defines an asynchronous generator, which yields promises or values resolved asynchronously.
- **`for await...of`**: This loop is used to consume values from an async generator, and it pauses until each promise resolves before continuing to the next iteration.
- **`yield`**: It allows the function to return values asynchronously one by one, pausing execution of the generator between each yield.

This pattern is useful when dealing with streams of asynchronous data, like processing a sequence of HTTP requests or reading data from a database asynchronously.

---

### **Conceptual and Practical**

### 41. How is `async/await` syntactic sugar for promises?

The `async/await` syntax in JavaScript is considered **syntactic sugar** for promises because it provides a more readable and declarative way to work with asynchronous code compared to directly chaining `.then()` and `.catch()` methods. Behind the scenes, `async/await` still uses promises to manage asynchronous operations. Here's a detailed breakdown:

---

### Key Features of `async/await` as Syntactic Sugar

1. **Readable Flow**:

   - `async/await` allows you to write asynchronous code that looks and behaves like synchronous code, making it easier to read and maintain.
   - The keyword `await` pauses the execution of an `async` function until the promise is resolved or rejected.

2. **Automatic Promise Handling**:

   - When you use `await`, JavaScript automatically waits for the promise to resolve and then returns the resolved value. If the promise is rejected, it throws an error, which can be caught with a `try...catch` block.

3. **Promises Under the Hood**:
   - Every `async` function automatically returns a promise. When you return a value from an `async` function, it resolves the promise. Throwing an error inside an `async` function rejects the promise.

---

### Code Examples: Promises vs. Async/Await

#### Using Promises

```javascript
function fetchData() {
  return new Promise((resolve, reject) => {
    setTimeout(() => resolve("Data fetched!"), 1000);
  });
}

fetchData()
  .then((data) => {
    console.log(data); // Output: Data fetched!
    return "Processing done!";
  })
  .then((message) => {
    console.log(message); // Output: Processing done!
  })
  .catch((error) => {
    console.error("Error:", error);
  });
```

#### Using Async/Await

```javascript
async function fetchDataAsync() {
  try {
    const data = await fetchData();
    console.log(data); // Output: Data fetched!
    const message = "Processing done!";
    console.log(message); // Output: Processing done!
  } catch (error) {
    console.error("Error:", error);
  }
}

fetchDataAsync();
```

---

### How `async/await` Works Under the Hood

#### Synchronous-Looking Flow

The `async/await` version above translates roughly to the following:

```javascript
function fetchDataAsync() {
  return fetchData()
    .then((data) => {
      console.log(data); // Output: Data fetched!
      return "Processing done!";
    })
    .then((message) => {
      console.log(message); // Output: Processing done!
    })
    .catch((error) => {
      console.error("Error:", error);
    });
}
```

---

### Key Differences

| Aspect             | Promises (`.then`)                 | `async/await`                        |
| ------------------ | ---------------------------------- | ------------------------------------ |
| **Readability**    | Uses chained `.then()` callbacks   | Linear, synchronous-looking code.    |
| **Error Handling** | `.catch()` for promise rejections  | `try...catch` for exceptions.        |
| **Chaining**       | Explicit return values             | Implicit chaining with `await`.      |
| **Debugging**      | Errors appear in chained callbacks | Errors appear inline with the logic. |

---

### Why Use `async/await`?

- **Improved Readability**: Complex asynchronous workflows are easier to follow.
- **Error Handling**: A `try...catch` block consolidates error management, making it intuitive.
- **Debugging**: Easier to debug as errors appear at the location of failure in the function body.

---

### Conclusion

While `async/await` simplifies working with promises, it's essentially just a different way of using them. The mechanics of resolving, rejecting, and chaining are handled behind the scenes, making your code cleaner and more maintainable without changing the underlying promise-based behavior.

### 42. What are the advantages of `async/await` over traditional promise chains?

The `async/await` syntax provides several advantages over traditional promise chains (`.then()` and `.catch()`) when working with asynchronous JavaScript. These advantages primarily center around readability, maintainability, and error handling. Here's a detailed breakdown:

---

### **Advantages of `async/await`**

#### 1. **Improved Readability**

- **Promise Chains**:
  - Complex workflows with multiple asynchronous operations often lead to deeply nested `.then()` calls or callback pyramids, making the code harder to read.
- **`async/await`**:
  - Provides a linear and synchronous-looking flow for asynchronous code, making it easier to understand.

**Example**:
Using Promise Chains:

```javascript
fetchData()
  .then((data) => processData(data))
  .then((result) => saveData(result))
  .then(() => console.log("All tasks completed!"))
  .catch((error) => console.error("Error:", error));
```

Using `async/await`:

```javascript
async function executeTasks() {
  try {
    const data = await fetchData();
    const result = await processData(data);
    await saveData(result);
    console.log("All tasks completed!");
  } catch (error) {
    console.error("Error:", error);
  }
}
```

---

#### 2. **Simplified Error Handling**

- **Promise Chains**:
  - Requires explicit `.catch()` blocks to handle errors, which can be cumbersome in nested or sequential operations.
- **`async/await`**:
  - Allows you to use `try...catch` blocks for error handling, consolidating logic and making it intuitive.

**Example**:
With Promise Chains:

```javascript
fetchData()
  .then((data) => processData(data))
  .catch((error) => console.error("Error in processing:", error))
  .then(() => saveData())
  .catch((error) => console.error("Error in saving:", error));
```

With `async/await`:

```javascript
async function executeTasks() {
  try {
    const data = await fetchData();
    const result = await processData(data);
    await saveData(result);
    console.log("All tasks completed!");
  } catch (error) {
    console.error("Error:", error);
  }
}
```

---

#### 3. **Easier Debugging**

- **Promise Chains**:
  - Errors often occur in `.then()` chains and may not show the exact location of failure in stack traces.
- **`async/await`**:
  - Errors appear in the function body, making them easier to debug as they pinpoint the exact line of failure.

---

#### 4. **Sequential Execution**

- **Promise Chains**:
  - Handling sequential asynchronous operations requires chaining `.then()` calls, which can be verbose and difficult to manage.
- **`async/await`**:
  - Allows you to handle sequential asynchronous operations with simple `await` calls.

**Example**:
Fetching data from multiple sources sequentially:
Using `async/await`:

```javascript
async function fetchAllData() {
  const data1 = await fetchData1();
  const data2 = await fetchData2();
  const data3 = await fetchData3();
  return [data1, data2, data3];
}
```

Using Promise Chains:

```javascript
fetchData1()
  .then((data1) => {
    return fetchData2().then((data2) => {
      return fetchData3().then((data3) => [data1, data2, data3]);
    });
  })
  .then((results) => console.log("All data:", results))
  .catch((error) => console.error("Error:", error));
```

---

#### 5. **Parallel Execution with Simplicity**

- **Promise Chains**:
  - Parallel operations with `Promise.all` are possible but may require more careful handling for readability.
- **`async/await`**:
  - Easily integrates with `Promise.all` for parallel execution while keeping code readable.

**Example**:

```javascript
async function fetchInParallel() {
  const [data1, data2, data3] = await Promise.all([
    fetchData1(),
    fetchData2(),
    fetchData3(),
  ]);
  console.log("All data:", data1, data2, data3);
}
```

---

#### 6. **Compatibility with Looping**

- **Promise Chains**:
  - Using promises in loops requires additional scaffolding, such as creating an array of promises and using `Promise.all`.
- **`async/await`**:
  - Works seamlessly within loops, making it easier to handle iterative asynchronous operations.

**Example**:

```javascript
async function processArray(array) {
  for (const item of array) {
    const result = await processItem(item);
    console.log(result);
  }
}
```

---

### **Summary of Advantages**

| Feature                  | Promises (`.then`)        | `async/await`                    |
| ------------------------ | ------------------------- | -------------------------------- |
| **Readability**          | Nested chains             | Linear, synchronous-looking code |
| **Error Handling**       | `.catch()` for each chain | Single `try...catch` block       |
| **Debugging**            | Indirect stack traces     | Inline error locations           |
| **Sequential Execution** | Verbose chaining          | Simple `await` calls             |
| **Parallel Execution**   | Requires `Promise.all`    | Combines well with `Promise.all` |
| **Looping**              | Complex setup             | Natural integration              |

---

### Conclusion

The `async/await` syntax is designed to simplify working with promises, improving code readability, maintainability, and error handling. It provides all the functionality of promises while reducing boilerplate and making asynchronous code easier to write and debug.

### 43. Write an `async` function that handles a long-running process and reports progress at regular intervals.

Here's an `async` function that simulates handling a long-running process while reporting progress at regular intervals:

---

### **Code**

```javascript
async function longRunningProcess(totalSteps, progressCallback) {
  for (let step = 1; step <= totalSteps; step++) {
    // Simulate a time-consuming operation
    await new Promise((resolve) => setTimeout(resolve, 500));

    // Report progress using the callback
    progressCallback(step, totalSteps);
  }
  console.log("Process completed!");
}

// Example usage of the longRunningProcess function
(async () => {
  const totalSteps = 10;

  // Progress callback function
  const progressCallback = (currentStep, totalSteps) => {
    const percentage = ((currentStep / totalSteps) * 100).toFixed(2);
    console.log(`Progress: ${currentStep}/${totalSteps} (${percentage}%)`);
  };

  console.log("Starting long-running process...");
  await longRunningProcess(totalSteps, progressCallback);
})();
```

---

### **How It Works**

1. **Parameters**:

   - `totalSteps`: The total number of steps in the long-running process.
   - `progressCallback`: A function that gets called at each step to report progress.

2. **Simulating Work**:

   - A `setTimeout` inside a `Promise` is used to simulate a time-consuming task for each step.

3. **Reporting Progress**:

   - The `progressCallback` function is invoked at each step with the current progress, allowing for real-time updates.

4. **Completion**:
   - When all steps are completed, a message is logged indicating the end of the process.

---

### **Example Output**

If `totalSteps = 10` and each step takes 500ms, the output will look like this:

```plaintext
Starting long-running process...
Progress: 1/10 (10.00%)
Progress: 2/10 (20.00%)
Progress: 3/10 (30.00%)
Progress: 4/10 (40.00%)
Progress: 5/10 (50.00%)
Progress: 6/10 (60.00%)
Progress: 7/10 (70.00%)
Progress: 8/10 (80.00%)
Progress: 9/10 (90.00%)
Progress: 10/10 (100.00%)
Process completed!
```

---

### **Use Cases**

- **Batch Processing**: Updating a UI with the progress of a batch operation.
- **File Upload/Download**: Reporting progress during file transfers.
- **Simulations**: Providing real-time updates during simulations or calculations.

### 44. How does `finally` work with `async/await`? Provide an example.

The `finally` block works with `async/await` in the same way it works with promises — it is used to execute code after a `try...catch` block, regardless of whether an exception was thrown or not. The `finally` block is executed after the `try` and `catch` blocks, making it useful for cleanup operations, like closing a file, releasing a resource, or stopping a loading indicator.

### **How It Works**

- **If the `async` function completes successfully**, the code inside the `finally` block is executed.
- **If an error is thrown**, the code inside the `catch` block runs, and then the code inside the `finally` block is executed.

The important point is that the `finally` block **always runs**, no matter whether the promise is fulfilled or rejected.

---

### **Example**

```javascript
async function fetchData() {
  try {
    console.log("Starting fetch...");
    // Simulating an asynchronous task
    let data = await new Promise((resolve, reject) => {
      setTimeout(() => resolve("Data fetched successfully!"), 1000);
      // To simulate an error, you can replace resolve with reject.
      // setTimeout(() => reject("Error fetching data!"), 1000);
    });
    console.log(data); // Only runs if the promise resolves
  } catch (error) {
    console.error("Error:", error); // Runs if the promise rejects
  } finally {
    console.log("Cleaning up..."); // Always runs, regardless of success or failure
  }
}

(async () => {
  await fetchData(); // Runs the fetchData function
})();
```

### **Explanation**

- **`try` block**: This is where you attempt to execute the asynchronous task, in this case, a simulated API call using `setTimeout`. If the promise resolves successfully, the result is logged.
- **`catch` block**: If the promise is rejected (simulating an error in the fetch), the error is caught and logged.
- **`finally` block**: Whether the task was successful or failed, the `finally` block runs after the `try` and `catch` blocks, ensuring that the "cleanup" message is always displayed.

### **Output (on Success)**

```plaintext
Starting fetch...
Data fetched successfully!
Cleaning up...
```

### **Output (on Failure)**

If you replace the `resolve` with `reject` inside the promise, the output will be:

```plaintext
Starting fetch...
Error: Error fetching data!
Cleaning up...
```

---

### **Use Case**

The `finally` block is particularly useful for cleanup tasks, such as:

- Closing connections (e.g., database or file handles).
- Hiding loading indicators.
- Resetting states after an operation, regardless of success or failure.

### **Important Notes**:

- The `finally` block **does not affect the return value** of the `async` function. Even if you return a value from the `finally` block, it is ignored. The return value from the `try` or `catch` block is what will be returned by the `async` function.

### 45. Write an `async` function that handles multiple tasks, but cancels all pending tasks if one fails.

To handle multiple tasks concurrently in an `async` function and cancel all pending tasks if one fails, we can use **Promise cancellation** and `Promise.all` with `try...catch`. JavaScript doesn't have built-in support for canceling promises, but we can implement a way to signal cancellation by using an external flag, such as with `AbortController` or manually rejecting promises when a task fails.

For this example, we'll simulate task cancellation by creating a mechanism that stops further processing when one task fails.

---

### **Example Code: Handling Multiple Tasks with Cancellation on Failure**

```javascript
async function performTask(id, shouldFail = false) {
  // Simulate a task taking some time
  return new Promise((resolve, reject) => {
    setTimeout(() => {
      if (shouldFail) {
        reject(`Task ${id} failed!`);
      } else {
        resolve(`Task ${id} completed successfully!`);
      }
    }, Math.random() * 2000); // Random delay between 0 and 2 seconds
  });
}

async function executeTasks() {
  const tasks = [performTask(1), performTask(2, true), performTask(3)];

  try {
    // Execute all tasks concurrently
    const results = await Promise.all(
      tasks.map((task) => task.catch((error) => error))
    );

    // Check results after execution
    for (const result of results) {
      if (result instanceof Error) {
        // If one task failed, cancel all tasks (e.g., reject others)
        throw new Error(
          "One of the tasks failed, cancelling all pending tasks!"
        );
      }
      console.log(result); // Log successful results
    }
  } catch (error) {
    console.error("Error:", error.message);
  }
}

executeTasks();
```

### **Explanation**

1. **`performTask` Function**:

   - This function simulates a task by returning a promise that resolves after a random timeout.
   - If the `shouldFail` argument is `true`, the task will reject instead of resolving, simulating a failure.

2. **`executeTasks` Function**:

   - This function attempts to run multiple tasks concurrently.
   - `Promise.all()` is used to execute all tasks at the same time. However, if any task fails, the rest of the tasks are also canceled.
   - Each task is wrapped with a `.catch()` method to ensure that we handle failures gracefully and prevent the entire process from crashing prematurely.
   - If one task fails, we throw an error to simulate the cancellation of all tasks. In a real scenario, we might use additional mechanisms (like `AbortController`) to cancel ongoing tasks.

3. **Handling Errors**:
   - If any task fails (i.e., an error is thrown or a promise is rejected), the `catch` block will log an error message and simulate the cancellation of all remaining tasks.

---

### **Output Example**

With `performTask(2, true)` causing a failure, the output might look like this:

```plaintext
Error: One of the tasks failed, cancelling all pending tasks!
```

If all tasks succeed, you'll see:

```plaintext
Task 1 completed successfully!
Task 3 completed successfully!
```

---

### **Cancellation in Practice**

JavaScript doesn't natively support canceling promises, but you can handle cancellation manually:

1. **AbortController**: For API requests or fetch calls, you can use `AbortController` to abort requests.
2. **Manual Cancellation**: You can pass an "abort" flag to each task, and when a failure occurs, manually reject the other tasks by using `Promise.reject()` or cancel ongoing operations.

This approach can be enhanced to handle cancellation more effectively with specific use cases, such as using `AbortController` in network requests.

### **Challenges**

### 46. Write a utility function `withTimeout` that wraps any async operation and adds a timeout.

Here’s the implementation of a utility function `withTimeout` that wraps any asynchronous operation and adds a timeout:

### Code

```javascript
function withTimeout(asyncOperation, timeoutMs) {
  return new Promise((resolve, reject) => {
    // Set up the timeout
    const timeoutId = setTimeout(() => {
      reject(new Error(`Operation timed out after ${timeoutMs} ms`));
    }, timeoutMs);

    // Execute the async operation
    asyncOperation()
      .then((result) => {
        clearTimeout(timeoutId); // Clear the timeout on success
        resolve(result); // Resolve with the result
      })
      .catch((error) => {
        clearTimeout(timeoutId); // Clear the timeout on error
        reject(error); // Reject with the error
      });
  });
}

// Example usage
async function mockAsyncOperation() {
  return new Promise((resolve) =>
    setTimeout(() => resolve("Operation completed"), 2000)
  );
}

async function runExample() {
  try {
    const result = await withTimeout(mockAsyncOperation, 1000); // Set a timeout of 1 second
    console.log(result);
  } catch (error) {
    console.error("Error:", error.message);
  }
}

runExample();
```

---

### Explanation

1. **Function Definition (`withTimeout`)**:

   - Takes two arguments:
     - `asyncOperation`: A function that returns a promise (the async operation to be wrapped).
     - `timeoutMs`: The maximum time (in milliseconds) to wait for the operation to complete.

2. **Timeout Setup**:

   - A `setTimeout` is created to reject the promise if the operation takes too long.

3. **Async Operation Execution**:

   - The provided `asyncOperation` is executed.
   - On success, the timeout is cleared using `clearTimeout`, and the result is resolved.
   - On failure, the timeout is cleared, and the error is propagated via rejection.

4. **Error Handling**:
   - If the timeout expires first, the promise is rejected with a descriptive error message.

---

### Example Output

For a mock operation that takes **2 seconds**, if the timeout is **1 second**:

```
Error: Operation timed out after 1000 ms
```

For a timeout of **3 seconds**:

```
Operation completed
```

---

### Use Cases

- Ensuring operations don’t hang indefinitely (e.g., API calls).
- Adding robust timeout handling to existing async workflows.

### 47. Implement a batch processing system using `async/await` where tasks are processed in groups of 5.

Here’s an implementation of a batch processing system using `async/await`, where tasks are processed in groups of 5:

### Code

```javascript
async function processInBatches(tasks, batchSize) {
  for (let i = 0; i < tasks.length; i += batchSize) {
    // Create a batch of tasks
    const batch = tasks.slice(i, i + batchSize);

    // Wait for all tasks in the batch to complete
    const results = await Promise.all(batch.map((task) => task()));

    // Log results of the current batch
    console.log(`Batch ${Math.floor(i / batchSize) + 1} results:`, results);
  }
}

// Example: Simulated async tasks
const createTask = (id) => {
  return async () => {
    await new Promise((res) => setTimeout(res, Math.random() * 1000));
    return `Task ${id} completed`;
  };
};

// Create an array of tasks
const tasks = Array.from({ length: 20 }, (_, i) => createTask(i + 1));

// Process tasks in batches of 5
processInBatches(tasks, 5);
```

---

### Explanation

1. **Function Definition (`processInBatches`)**:

   - Takes two parameters:
     - `tasks`: An array of asynchronous task functions.
     - `batchSize`: The number of tasks to process concurrently in each batch.

2. **Batch Creation**:

   - The tasks array is sliced into smaller batches of size `batchSize`.

3. **Batch Execution**:

   - Each batch is processed concurrently using `Promise.all`, which waits for all promises in the batch to resolve.

4. **Logging Results**:

   - Results of each batch are logged for visibility.

5. **Simulated Async Tasks**:
   - `createTask` generates a function that simulates an asynchronous task by waiting for a random time before resolving.

---

### Example Output

For 20 tasks processed in batches of 5:

```
Batch 1 results: [ 'Task 1 completed', 'Task 2 completed', 'Task 3 completed', 'Task 4 completed', 'Task 5 completed' ]
Batch 2 results: [ 'Task 6 completed', 'Task 7 completed', 'Task 8 completed', 'Task 9 completed', 'Task 10 completed' ]
Batch 3 results: [ 'Task 11 completed', 'Task 12 completed', 'Task 13 completed', 'Task 14 completed', 'Task 15 completed' ]
Batch 4 results: [ 'Task 16 completed', 'Task 17 completed', 'Task 18 completed', 'Task 19 completed', 'Task 20 completed' ]
```

---

### Key Features

- **Concurrency Control**: Only `batchSize` tasks are executed at any given time, preventing overload.
- **Asynchronous Processing**: Tasks within a batch run in parallel, leveraging the power of `Promise.all`.
- **Scalability**: Easily adaptable for larger task sets or different batch sizes.

### 48. Write a recursive `async` function to fetch paginated data until no more pages are left.

Here’s a recursive `async` function to fetch paginated data until no more pages are left. The function simulates fetching paginated data from an API, where each response includes the current page's data and a `nextPage` link if more data exists.

---

### Code

```javascript
async function fetchPaginatedData(apiUrl, collectedData = []) {
  try {
    // Simulate an API request (replace this with an actual fetch call)
    const response = await mockApiRequest(apiUrl);

    // Collect data from the current page
    collectedData.push(...response.data);

    console.log(`Fetched data from page: ${response.page}`);

    // If there's a next page, recursively fetch it
    if (response.nextPage) {
      return fetchPaginatedData(response.nextPage, collectedData);
    } else {
      // No more pages, return the collected data
      return collectedData;
    }
  } catch (error) {
    console.error("Error fetching data:", error);
    throw error;
  }
}

// Example: Mock API request function
async function mockApiRequest(apiUrl) {
  return new Promise((resolve) => {
    setTimeout(() => {
      const page = parseInt(apiUrl.split("=")[1], 10); // Extract page number from URL
      resolve({
        page,
        data: [`Item ${page * 1}`, `Item ${page * 2}`, `Item ${page * 3}`],
        nextPage:
          page < 3 ? `https://api.example.com/data?page=${page + 1}` : null, // Only 3 pages
      });
    }, 1000); // Simulate network delay
  });
}

// Example usage
(async () => {
  const initialUrl = "https://api.example.com/data?page=1";
  const allData = await fetchPaginatedData(initialUrl);
  console.log("All data fetched:", allData);
})();
```

---

### Explanation

1. **Recursive Function (`fetchPaginatedData`)**:

   - Accepts the `apiUrl` for the current page and an array `collectedData` to accumulate results.
   - Calls an asynchronous function (`mockApiRequest`) to fetch the current page's data.

2. **Base Case**:

   - If the API response indicates there is no `nextPage`, the recursion stops, and the `collectedData` array is returned.

3. **Recursive Case**:

   - If there is a `nextPage`, the function calls itself with the new URL (`response.nextPage`).

4. **Mock API Request**:

   - Simulates fetching paginated data from an API.
   - Returns a simulated `response` object with:
     - `page`: Current page number.
     - `data`: Data for the current page.
     - `nextPage`: URL of the next page, or `null` if there are no more pages.

5. **Usage**:
   - Starts the recursive fetching process with the initial URL and logs the aggregated data when done.

---

### Output Example

```plaintext
Fetched data from page: 1
Fetched data from page: 2
Fetched data from page: 3
All data fetched: [ 'Item 1', 'Item 2', 'Item 3', 'Item 2', 'Item 4', 'Item 6', 'Item 3', 'Item 6', 'Item 9' ]
```

---

### Advantages

- **Simplified Control Flow**: Recursion naturally handles chaining of asynchronous requests until the stopping condition (`nextPage === null`).
- **Flexibility**: The function can handle any number of pages, as long as the API provides a `nextPage` property.
- **Scalability**: Accumulates data across pages efficiently.

### 49. Create a script that performs multiple API calls in sequence but stops on the first failure.

Here’s a script that performs multiple API calls in sequence using `async/await` and stops on the first failure by catching errors.

---

### Code

```javascript
async function performApiCallsInSequence(apiUrls) {
  try {
    for (const url of apiUrls) {
      console.log(`Fetching from: ${url}`);

      // Simulate an API request (replace with an actual fetch call)
      const result = await mockApiRequest(url);

      console.log(`Result from ${url}:`, result);
    }

    console.log("All API calls succeeded.");
  } catch (error) {
    console.error("Error occurred:", error.message);
    console.log("Stopping further execution.");
  }
}

// Mock API request function to simulate success and failure
async function mockApiRequest(url) {
  return new Promise((resolve, reject) => {
    setTimeout(() => {
      // Simulate a failure for one specific URL
      if (url.includes("fail")) {
        reject(new Error(`Failed to fetch data from ${url}`));
      } else {
        resolve(`Data from ${url}`);
      }
    }, 1000); // Simulate network delay
  });
}

// Example usage
const apiUrls = [
  "https://api.example.com/data1",
  "https://api.example.com/data2",
  "https://api.example.com/fail", // This URL will trigger a failure
  "https://api.example.com/data4",
];

performApiCallsInSequence(apiUrls);
```

---

### Explanation

1. **Sequential Execution**:

   - The script uses a `for...of` loop to iterate through the `apiUrls` array.
   - Each API call is awaited, ensuring that the calls happen in sequence.

2. **Error Handling**:

   - If an error occurs during an API call, the `catch` block logs the error and stops further execution.

3. **Mock API Request**:

   - Simulates an API request with a delay.
   - Resolves for successful URLs and rejects for URLs containing the word `"fail"`.

4. **Stopping on Failure**:
   - The first failure (rejected promise) triggers the `catch` block, and no further API calls are made.

---

### Output Example

For the provided `apiUrls`:

```plaintext
Fetching from: https://api.example.com/data1
Result from https://api.example.com/data1: Data from https://api.example.com/data1
Fetching from: https://api.example.com/data2
Result from https://api.example.com/data2: Data from https://api.example.com/data2
Fetching from: https://api.example.com/fail
Error occurred: Failed to fetch data from https://api.example.com/fail
Stopping further execution.
```

---

### Key Features

- **Sequential Execution**: Ensures that each API call waits for the previous one to finish.
- **Failure Handling**: Stops execution on the first failure.
- **Modularity**: Replace `mockApiRequest` with `fetch` or another API client for real-world use.

### 50. Combine `async/await` with a `Map` or `Reduce` operation to process an array of promises.

Here’s an example of combining `async/await` with `Map` and `Reduce` operations to process an array of promises efficiently:

---

### **Using `Map`**

```javascript
async function processWithMap(promises) {
  const results = await Promise.all(
    promises.map(async (promise, index) => {
      const result = await promise();
      console.log(`Processed promise ${index + 1}: ${result}`);
      return result;
    })
  );
  return results;
}

// Example: Simulated async tasks
const tasks = [
  () => new Promise((res) => setTimeout(() => res("Task 1 completed"), 1000)),
  () => new Promise((res) => setTimeout(() => res("Task 2 completed"), 500)),
  () => new Promise((res) => setTimeout(() => res("Task 3 completed"), 800)),
];

// Process tasks using Map
(async () => {
  const results = await processWithMap(tasks);
  console.log("All tasks processed:", results);
})();
```

**Explanation**:

1. Each promise is transformed using `.map` into an asynchronous operation.
2. `Promise.all` ensures that all promises are awaited in parallel.
3. Results are returned as an array of resolved values.

**Output**:

```plaintext
Processed promise 1: Task 1 completed
Processed promise 2: Task 2 completed
Processed promise 3: Task 3 completed
All tasks processed: [ 'Task 1 completed', 'Task 2 completed', 'Task 3 completed' ]
```

---

### **Using `Reduce`**

```javascript
async function processWithReduce(promises) {
  const results = await promises.reduce(async (accPromise, promise, index) => {
    const acc = await accPromise; // Wait for accumulated results
    const result = await promise(); // Process current promise
    console.log(`Processed promise ${index + 1}: ${result}`);
    return [...acc, result]; // Accumulate results
  }, Promise.resolve([])); // Start with an empty resolved Promise
  return results;
}

// Example: Simulated async tasks
const tasks = [
  () => new Promise((res) => setTimeout(() => res("Task 1 completed"), 1000)),
  () => new Promise((res) => setTimeout(() => res("Task 2 completed"), 500)),
  () => new Promise((res) => setTimeout(() => res("Task 3 completed"), 800)),
];

// Process tasks using Reduce
(async () => {
  const results = await processWithReduce(tasks);
  console.log("All tasks processed:", results);
})();
```

**Explanation**:

1. The `reduce` method processes promises sequentially by accumulating results into an array.
2. Each iteration waits for the current promise to resolve before moving to the next.
3. This approach ensures sequential processing and is useful when tasks need to be processed in order.

**Output**:

```plaintext
Processed promise 1: Task 1 completed
Processed promise 2: Task 2 completed
Processed promise 3: Task 3 completed
All tasks processed: [ 'Task 1 completed', 'Task 2 completed', 'Task 3 completed' ]
```

---

### **Comparison**

| Approach              | Execution Order | Parallelism        | Use Case                                       |
| --------------------- | --------------- | ------------------ | ---------------------------------------------- |
| **Map + Promise.all** | Parallel        | High               | Independent tasks that can run concurrently.   |
| **Reduce**            | Sequential      | None (1 at a time) | Dependent tasks or tasks needing strict order. |

---

### **Bonus**

### How does async/await handle backpressure (e.g., managing multiple async operations to avoid overload)?

### **Backpressure in the Context of `async/await`**

Backpressure occurs when a system is overwhelmed by incoming asynchronous tasks or data it cannot process efficiently. When using `async/await` in JavaScript, you can manage backpressure by controlling how and when asynchronous operations are initiated and resolved. This is crucial in scenarios like making API requests, processing streams, or handling I/O tasks to avoid overloading the system.

---

### **Strategies to Handle Backpressure with `async/await`**

1. **Sequential Execution**

   - Process one task at a time, waiting for the previous task to complete before starting the next.
   - This is the simplest way to manage backpressure.

   **Code Example:**

   ```javascript
   async function processSequentially(tasks) {
     for (const task of tasks) {
       const result = await task();
       console.log(result);
     }
   }

   // Example usage
   const tasks = [
     () => Promise.resolve("Task 1 completed"),
     () => Promise.resolve("Task 2 completed"),
     () => Promise.resolve("Task 3 completed"),
   ];
   processSequentially(tasks); // Tasks are processed one by one.
   ```

2. **Limited Parallelism**

   - Use a limited number of concurrent tasks to prevent overwhelming the system.
   - Implement a pool of workers or a concurrency limit.

   **Code Example:**

   ```javascript
   async function processWithLimit(tasks, limit) {
     const activeTasks = new Set();

     for (const task of tasks) {
       // Start a task and add it to the active set
       const promise = task().then((result) => {
         console.log(result);
         activeTasks.delete(promise); // Remove completed task
       });

       activeTasks.add(promise);

       // Wait if active tasks reach the limit
       if (activeTasks.size >= limit) {
         await Promise.race(activeTasks);
       }
     }

     // Wait for all remaining tasks to complete
     await Promise.all(activeTasks);
   }

   // Example usage
   const tasks = [
     () =>
       new Promise((res) => setTimeout(() => res("Task 1 completed"), 1000)),
     () => new Promise((res) => setTimeout(() => res("Task 2 completed"), 500)),
     () =>
       new Promise((res) => setTimeout(() => res("Task 3 completed"), 1500)),
     () => new Promise((res) => setTimeout(() => res("Task 4 completed"), 200)),
   ];
   processWithLimit(tasks, 2); // Only 2 tasks run concurrently.
   ```

3. **Batch Processing**

   - Divide tasks into smaller batches and process each batch sequentially while allowing parallel execution within a batch.

   **Code Example:**

   ```javascript
   async function processInBatches(tasks, batchSize) {
     for (let i = 0; i < tasks.length; i += batchSize) {
       const batch = tasks.slice(i, i + batchSize);
       const results = await Promise.all(batch.map((task) => task()));
       results.forEach((result) => console.log(result));
     }
   }

   // Example usage
   const tasks = [
     () => Promise.resolve("Task 1 completed"),
     () => Promise.resolve("Task 2 completed"),
     () => Promise.resolve("Task 3 completed"),
     () => Promise.resolve("Task 4 completed"),
   ];
   processInBatches(tasks, 2); // Process tasks in batches of 2.
   ```

4. **Dynamic Throttling**
   - Adjust the concurrency dynamically based on system conditions, such as CPU usage, memory limits, or external feedback.

---

### **When to Use Each Strategy**

1. **Sequential Execution**:

   - When tasks must be processed in order, or each task depends on the result of the previous one.
   - Simplest way but slowest for large sets of tasks.

2. **Limited Parallelism**:

   - Best for handling a large number of tasks while preventing resource exhaustion.
   - Useful for I/O-bound operations like network requests.

3. **Batch Processing**:

   - Ideal for tasks that can be grouped into independent sets, such as bulk data processing.

4. **Dynamic Throttling**:
   - Use when system conditions or external factors influence the rate of task execution.

---

### **Benefits of Using `async/await` for Backpressure**

- **Readability**: Simplifies the flow of managing asynchronous tasks.
- **Error Handling**: Errors can be caught with `try/catch`, improving reliability.
- **Fine-Grained Control**: Explicit control over concurrency, batching, and execution flow.

### Can you mix callbacks, promises, and `async/await` in the same program? When would this be useful?

Yes, you can mix **callbacks**, **promises**, and **async/await** in the same program. While it’s generally best to stick to one paradigm for consistency and readability, there are situations where mixing these patterns is useful or necessary.

---

### **When Mixing Is Useful**

1. **Interfacing with Legacy Code**:

   - Older APIs might still use callbacks, but modern parts of your code may use promises or `async/await`. Wrapping callbacks in promises can bridge the gap between the two.

2. **Incremental Migration**:

   - If you're migrating a codebase from callbacks to promises or `async/await`, mixing allows you to gradually refactor without rewriting everything at once.

3. **Third-Party Libraries**:

   - Some third-party libraries or APIs may only support callbacks, while your application logic uses promises or `async/await`.

4. **Complex Flows**:
   - Sometimes combining these paradigms can simplify certain tasks, such as handling race conditions, managing multiple asynchronous processes, or ensuring compatibility between parts of the code.

---

### **Example: Mixing Callbacks, Promises, and Async/Await**

Here’s an example program that demonstrates mixing:

```javascript
// Simulated callback-based function
function fetchDataCallback(url, callback) {
  setTimeout(() => {
    if (url) {
      callback(null, { data: "Callback Data from " + url });
    } else {
      callback("Error: No URL provided");
    }
  }, 1000);
}

// Promise wrapper for the callback function
function fetchDataPromise(url) {
  return new Promise((resolve, reject) => {
    fetchDataCallback(url, (error, result) => {
      if (error) {
        reject(error);
      } else {
        resolve(result);
      }
    });
  });
}

// Using async/await to handle the promise
async function fetchDataAsync(url) {
  try {
    const result = await fetchDataPromise(url);
    console.log("Async/Await Result:", result);
  } catch (error) {
    console.error("Error in Async/Await:", error);
  }
}

// Mixing paradigms
fetchDataCallback("http://example.com", (err, result) => {
  if (err) {
    console.error("Callback Error:", err);
  } else {
    console.log("Callback Result:", result);

    // Using the Promise-based function
    fetchDataPromise("http://example.com")
      .then((data) => {
        console.log("Promise Result:", data);

        // Using async/await after the promise
        fetchDataAsync("http://example.com");
      })
      .catch((promiseError) => {
        console.error("Promise Error:", promiseError);
      });
  }
});
```

---

### **Output**

```plaintext
Callback Result: { data: 'Callback Data from http://example.com' }
Promise Result: { data: 'Callback Data from http://example.com' }
Async/Await Result: { data: 'Callback Data from http://example.com' }
```

---

### **Explanation of the Example**

1. **Callback-Based API**:

   - `fetchDataCallback` is a simulated function that takes a URL and a callback.
   - It uses `setTimeout` to mimic asynchronous behavior.

2. **Promise Wrapper**:

   - `fetchDataPromise` wraps the callback-based function in a promise, making it compatible with promise-based code and `async/await`.

3. **Async/Await**:

   - `fetchDataAsync` uses `await` to handle the promise returned by `fetchDataPromise`.

4. **Mixing Paradigms**:
   - The callback-based function is used initially.
   - Its result is passed into the promise-based function.
   - Finally, the promise is handled using `async/await`.

---

### **Best Practices**

- Avoid overcomplicating your code with too many paradigms unless necessary.
- Prefer promises or `async/await` for new code for better readability and maintainability.
- Use utilities like `util.promisify` (in Node.js) to easily convert callback-based functions to promises.
